Workbook

Sheet Resumen
A1: Resumen General — FV (Nov 2025 a May 2026)
A3: Resumen financiero mensual
A4: Mes | B4: Ingresos | C4: Egresos | D4: Pagado | E4: Pendiente | F4: Balance (Ing-Pag-Eg)
A5: Nov | B5: 736500.8 | C5: 12950 | D5: 743476 | E5: 329762 | F5: =B5-D5-C5 -> -19925.2
A6: Dic | B6: 1758496.8 | C6: 42850 | D6: 1811975 | E6: 742446.26 | F6: =B6-D6-C6 -> -96328.22
A7: Ene | B7: 1008213.1 | C7: 0 | D7: 605682.21 | E7: 783233.22 | F7: =B7-D7-C7 -> 402530.87
A8: Feb | B8: 1214504 | C8: 0 | D8: 844914.57 | E8: 927193.04 | F8: =B8-D8-C8 -> 369589.43
A9: Mar | B9: 1322706 | C9: 75850 | D9: 809867.03 | E9: 900505.74 | F9: =B9-D9-C9 -> 436988.97
A10: Abr | B10: 1382415.3 | C10: 92750 | D10: 1198456.7 | E10: 543865.2 | F10: =B10-D10-C10 -> 91208.6
A11: May | B11: 1064879.8 | C11: 82050 | D11: 1037132.1 | E11: 1019588.4 | F11: =B11-D11-C11 -> -54302.284
A12: TOTAL | B12: =SUM(B5:B11) -> 8487715.8 | C12: =SUM(C5:C11) -> 306450 | D12: =SUM(D5:D11) -> 7051503.6 | E12: =SUM(E5:E11) -> 5246593.9 | F12: =SUM(F5:F11) -> 1129762.2
A14: Nota: Ingresos y Egresos provienen de las secciones "RESUMEN" de cada hoja semanal (no de BD Gastos).
A16: Acumulado mensual por categoría — Pago
A17: Categoría | B17: Nov | C17: Dic | D17: Ene | E17: Feb | F17: Mar | G17: Abr | H17: May | I17: Total
A18: Nómina/Personal | B18: ='Nómina-Personal (Pago)'!B29 -> 650006 | C18: ='Nómina-Personal (Pago)'!C29 -> 972504.75 | D18: ='Nómina-Personal (Pago)'!D29 -> 519300 | E18: ='Nómina-Personal (Pago)'!E29 -> 667778.29 | F18: ='Nómina-Personal (Pago)'!F29 -> 614677.14 | G18: ='Nómina-Personal (Pago)'!G29 -> 811856.43 | H18: ='Nómina-Personal (Pago)'!H29 -> 673111.09 | I18: =SUM(B18:H18) -> 4909233.7
A19: Empaque/Material | B19: ='Empaque-Material (Pago)'!B34 -> 15000 | C19: ='Empaque-Material (Pago)'!C34 -> 95580.39 | D19: ='Empaque-Material (Pago)'!D34 -> 34481.54 | E19: ='Empaque-Material (Pago)'!E34 -> 124017.68 | F19: ='Empaque-Material (Pago)'!F34 -> 29668.1 | G19: ='Empaque-Material (Pago)'!G34 -> 227823.73 | H19: ='Empaque-Material (Pago)'!H34 -> 215479.03 | I19: =SUM(B19:H19) -> 742050.47
A20: Otros | B20: ='Otros (Pago)'!B35 -> 0 | C20: ='Otros (Pago)'!C35 -> 638935.4 | D20: ='Otros (Pago)'!D35 -> 2041.71 | E20: ='Otros (Pago)'!E35 -> 36900 | F20: ='Otros (Pago)'!F35 -> 132560.41 | G20: ='Otros (Pago)'!G35 -> 9159.56 | H20: ='Otros (Pago)'!H35 -> 18269 | I20: =SUM(B20:H20) -> 837866.08
A21: Servicios | B21: ='Servicios (Pago)'!B19 -> 24000 | C21: ='Servicios (Pago)'!C19 -> 44954.48 | D21: ='Servicios (Pago)'!D19 -> 19858.96 | E21: ='Servicios (Pago)'!E19 -> 16218.6 | F21: ='Servicios (Pago)'!F19 -> 32961.384 | G21: ='Servicios (Pago)'!G19 -> 66919.83 | H21: ='Servicios (Pago)'!H19 -> 62176.164 | I21: =SUM(B21:H21) -> 267089.42
A22: Impuestos | B22: ='Impuestos (Pago)'!B14 -> 17470 | C22: ='Impuestos (Pago)'!C14 -> 10000 | D22: ='Impuestos (Pago)'!D14 -> 30000 | E22: ='Impuestos (Pago)'!E14 -> 0 | F22: ='Impuestos (Pago)'!F14 -> 0 | G22: ='Impuestos (Pago)'!G14 -> 63929.13 | H22: ='Impuestos (Pago)'!H14 -> 65367.8 | I22: =SUM(B22:H22) -> 186766.93
A23: Producto/Fruta | B23: ='Producto-Fruta (Pago)'!B7 -> 37000 | C23: ='Producto-Fruta (Pago)'!C7 -> 50000 | D23: ='Producto-Fruta (Pago)'!D7 -> 0 | E23: ='Producto-Fruta (Pago)'!E7 -> 0 | F23: ='Producto-Fruta (Pago)'!F7 -> 0 | G23: ='Producto-Fruta (Pago)'!G7 -> 18768 | H23: ='Producto-Fruta (Pago)'!H7 -> 0 | I23: =SUM(B23:H23) -> 105768
A24: LAR/Otros | B24: ='LAR-Otros (Pago)'!B7 -> 0 | C24: ='LAR-Otros (Pago)'!C7 -> 0 | D24: ='LAR-Otros (Pago)'!D7 -> 0 | E24: ='LAR-Otros (Pago)'!E7 -> 0 | F24: ='LAR-Otros (Pago)'!F7 -> 0 | G24: ='LAR-Otros (Pago)'!G7 -> 0 | H24: ='LAR-Otros (Pago)'!H7 -> 2729 | I24: =SUM(B24:H24) -> 2729
A25: TOTAL PAGADO | B25: =SUM(B18:B24) -> 743476 | C25: =SUM(C18:C24) -> 1811975 | D25: =SUM(D18:D24) -> 605682.21 | E25: =SUM(E18:E24) -> 844914.57 | F25: =SUM(F18:F24) -> 809867.03 | G25: =SUM(G18:G24) -> 1198456.7 | H25: =SUM(H18:H24) -> 1037132.1 | I25: =SUM(I18:I24) -> 7051503.6
A27: Acumulado mensual por categoría — Pendiente
A28: Categoría | B28: Nov | C28: Dic | D28: Ene | E28: Feb | F28: Mar | G28: Abr | H28: May | I28: Total
A29: Nómina/Personal | B29: ='Nómina-Personal (Pendiente)'!B29 -> 238542 | C29: ='Nómina-Personal (Pendiente)'!C29 -> 518583.7 | D29: ='Nómina-Personal (Pendiente)'!D29 -> 427925.48 | E29: ='Nómina-Personal (Pendiente)'!E29 -> 463426.2 | F29: ='Nómina-Personal (Pendiente)'!F29 -> 366750 | G29: ='Nómina-Personal (Pendiente)'!G29 -> 104560.02 | H29: ='Nómina-Personal (Pendiente)'!H29 -> 145297.8 | I29: =SUM(B29:H29) -> 2265085.2
A30: Empaque/Material | B30: ='Empaque-Material (Pendiente)'!B34 -> 48720 | C30: ='Empaque-Material (Pendiente)'!C34 -> 54050 | D30: ='Empaque-Material (Pendiente)'!D34 -> 145369.6 | E30: ='Empaque-Material (Pendiente)'!E34 -> 179238 | F30: ='Empaque-Material (Pendiente)'!F34 -> 335815.74 | G30: ='Empaque-Material (Pendiente)'!G34 -> 281300.22 | H30: ='Empaque-Material (Pendiente)'!H34 -> 238352.37 | I30: =SUM(B30:H30) -> 1282845.9
A31: Otros | B31: ='Otros (Pendiente)'!B35 -> 20000 | C31: ='Otros (Pendiente)'!C35 -> 97000 | D31: ='Otros (Pendiente)'!D35 -> 10839.94 | E31: ='Otros (Pendiente)'!E35 -> 23528.84 | F31: ='Otros (Pendiente)'!F35 -> 70000 | G31: ='Otros (Pendiente)'!G35 -> 51186.36 | H31: ='Otros (Pendiente)'!H35 -> 259315.55 | I31: =SUM(B31:H31) -> 531870.69
A32: Servicios | B32: ='Servicios (Pendiente)'!B19 -> 22500 | C32: ='Servicios (Pendiente)'!C19 -> 72812.56 | D32: ='Servicios (Pendiente)'!D19 -> 30198.2 | E32: ='Servicios (Pendiente)'!E19 -> 0 | F32: ='Servicios (Pendiente)'!F19 -> 2940 | G32: ='Servicios (Pendiente)'!G19 -> 49818.6 | H32: ='Servicios (Pendiente)'!H19 -> 59601.16 | I32: =SUM(B32:H32) -> 237870.52
A33: Impuestos | B33: ='Impuestos (Pendiente)'!B14 -> 0 | C33: ='Impuestos (Pendiente)'!C14 -> 0 | D33: ='Impuestos (Pendiente)'!D14 -> 27900 | E33: ='Impuestos (Pendiente)'!E14 -> 120000 | F33: ='Impuestos (Pendiente)'!F14 -> 125000 | G33: ='Impuestos (Pendiente)'!G14 -> 57000 | H33: ='Impuestos (Pendiente)'!H14 -> 163021.54 | I33: =SUM(B33:H33) -> 492921.54
A34: Producto/Fruta | B34: ='Producto-Fruta (Pendiente)'!B7 -> 0 | C34: ='Producto-Fruta (Pendiente)'!C7 -> 0 | D34: ='Producto-Fruta (Pendiente)'!D7 -> 0 | E34: ='Producto-Fruta (Pendiente)'!E7 -> 0 | F34: ='Producto-Fruta (Pendiente)'!F7 -> 0 | G34: ='Producto-Fruta (Pendiente)'!G7 -> 0 | H34: ='Producto-Fruta (Pendiente)'!H7 -> 0 | I34: =SUM(B34:H34) -> 0
A35: LAR/Otros | B35: ='LAR-Otros (Pendiente)'!B7 -> 0 | C35: ='LAR-Otros (Pendiente)'!C7 -> 0 | D35: ='LAR-Otros (Pendiente)'!D7 -> 141000 | E35: ='LAR-Otros (Pendiente)'!E7 -> 141000 | F35: ='LAR-Otros (Pendiente)'!F7 -> 0 | G35: ='LAR-Otros (Pendiente)'!G7 -> 0 | H35: ='LAR-Otros (Pendiente)'!H7 -> 154000 | I35: =SUM(B35:H35) -> 436000
A36: TOTAL PENDIENTE | B36: =SUM(B29:B35) -> 329762 | C36: =SUM(C29:C35) -> 742446.26 | D36: =SUM(D29:D35) -> 783233.22 | E36: =SUM(E29:E35) -> 927193.04 | F36: =SUM(F29:F35) -> 900505.74 | G36: =SUM(G29:G35) -> 543865.2 | H36: =SUM(H29:H35) -> 1019588.4 | I36: =SUM(I29:I35) -> 5246593.9

Sheet Ingresos
A1: Acumulado mensual — Ingresos
A3: Mes | B3: Nov | C3: Dic | D3: Ene | E3: Feb | F3: Mar | G3: Abr | H3: May | I3: Total
A4: Ingresos | B4: =Resumen!B5 -> 736500.8 | C4: =Resumen!B6 -> 1758496.8 | D4: =Resumen!B7 -> 1008213.1 | E4: =Resumen!B8 -> 1214504 | F4: =Resumen!B9 -> 1322706 | G4: =Resumen!B10 -> 1382415.3 | H4: =Resumen!B11 -> 1064879.8 | I4: =SUM(B4:H4) -> 8487715.8
A5: TOTAL INGRESOS | B5: =B4 -> 736500.8 | C5: =C4 -> 1758496.8 | D5: =D4 -> 1008213.1 | E5: =E4 -> 1214504 | F5: =F4 -> 1322706 | G5: =G4 -> 1382415.3 | H5: =H4 -> 1064879.8 | I5: =I4 -> 8487715.8

Sheet Egresos
A1: Acumulado mensual — Egresos
A3: Mes | B3: Nov | C3: Dic | D3: Ene | E3: Feb | F3: Mar | G3: Abr | H3: May | I3: Total
A4: Egresos | B4: =Resumen!C5 -> 12950 | C4: =Resumen!C6 -> 42850 | D4: =Resumen!C7 -> 0 | E4: =Resumen!C8 -> 0 | F4: =Resumen!C9 -> 75850 | G4: =Resumen!C10 -> 92750 | H4: =Resumen!C11 -> 82050 | I4: =SUM(B4:H4) -> 306450
A5: TOTAL EGRESOS | B5: =B4 -> 12950 | C5: =C4 -> 42850 | D5: =D4 -> 0 | E5: =E4 -> 0 | F5: =F4 -> 75850 | G5: =G4 -> 92750 | H5: =H4 -> 82050 | I5: =I4 -> 306450

Sheet Balance
A1: Acumulado mensual — Balance (Ing - Pag - Eg)
A3: Mes | B3: Nov | C3: Dic | D3: Ene | E3: Feb | F3: Mar | G3: Abr | H3: May | I3: Total
A4: Balance | B4: =Resumen!F5 -> -19925.2 | C4: =Resumen!F6 -> -96328.22 | D4: =Resumen!F7 -> 402530.87 | E4: =Resumen!F8 -> 369589.43 | F4: =Resumen!F9 -> 436988.97 | G4: =Resumen!F10 -> 91208.6 | H4: =Resumen!F11 -> -54302.284 | I4: =SUM(B4:H4) -> 1129762.2
A5: TOTAL BALANCE | B5: =B4 -> -19925.2 | C5: =C4 -> -96328.22 | D5: =D4 -> 402530.87 | E5: =E4 -> 369589.43 | F5: =F4 -> 436988.97 | G5: =G4 -> 91208.6 | H5: =H4 -> -54302.284 | I5: =I4 -> 1129762.2

Sheet 📊 Nómina-Personal
A1: Detalle mensual por concepto — Nómina/Personal
A2: Concepto | B2: Nov | E2: Dic | H2: Ene | K2: Feb | N2: Mar | Q2: Abr | T2: May | W2: TOTAL
B3: Pago | C3: Pendiente | D3: Total | E3: Pago | F3: Pendiente | G3: Total | H3: Pago | I3: Pendiente | J3: Total | K3: Pago | L3: Pendiente | M3: Total | N3: Pago | O3: Pendiente | P3: Total | Q3: Pago | R3: Pendiente | S3: Total | T3: Pago | U3: Pendiente | V3: Total | W3: Pago | X3: Pendiente | Y3: Total
A4: NOMINA FV | B4: 355000 | D4: =B4+C4 -> 355000 | E4: 609298 | G4: =E4+F4 -> 609298 | H4: 383000 | I4: 22000 | J4: =H4+I4 -> 405000 | K4: 418000 | L4: 122500 | M4: =K4+L4 -> 540500 | N4: 435000 | O4: 170000 | P4: =N4+O4 -> 605000 | Q4: 403000 | S4: =Q4+R4 -> 403000 | T4: 440000 | V4: =T4+U4 -> 440000 | W4: =B4+E4+H4+K4+N4+Q4+T4 -> 3043298 | X4: =C4+F4+I4+L4+O4+R4+U4 -> 314500 | Y4: =W4+X4 -> 3357798
A5: NOMINA CXM | B5: 73000 | D5: =B5+C5 -> 73000 | E5: 65852.5 | G5: =E5+F5 -> 65852.5 | H5: 68200 | I5: 17450 | J5: =H5+I5 -> 85650 | K5: 70450 | L5: 20000 | M5: =K5+L5 -> 90450 | N5: 86850 | O5: 8950 | P5: =N5+O5 -> 95800 | Q5: 92750 | S5: =Q5+R5 -> 92750 | T5: 98300 | V5: =T5+U5 -> 98300 | W5: =B5+E5+H5+K5+N5+Q5+T5 -> 555402.5 | X5: =C5+F5+I5+L5+O5+R5+U5 -> 46400 | Y5: =W5+X5 -> 601802.5
A6: RAISA | B6: 80000 | C6: 50136 | D6: =B6+C6 -> 130136 | F6: 100000 | G6: =E6+F6 -> 100000 | I6: 20000 | J6: =H6+I6 -> 20000 | K6: 86783.47 | L6: 79105 | M6: =K6+L6 -> 165888.47 | N6: 54415.44 | O6: 80000 | P6: =N6+O6 -> 134415.44 | Q6: 40426.65 | R6: 70000 | S6: =Q6+R6 -> 110426.65 | T6: 68302.86 | U6: 40000 | V6: =T6+U6 -> 108302.86 | W6: =B6+E6+H6+K6+N6+Q6+T6 -> 329928.42 | X6: =C6+F6+I6+L6+O6+R6+U6 -> 439241 | Y6: =W6+X6 -> 769169.42
A7: ARTURO GUERRERO | B7: 80000 | C7: 50000 | D7: =B7+C7 -> 130000 | E7: 160000 | F7: 50000 | G7: =E7+F7 -> 210000 | J7: =H7+I7 -> 0 | M7: =K7+L7 -> 0 | P7: =N7+O7 -> 0 | S7: =Q7+R7 -> 0 | V7: =T7+U7 -> 0 | W7: =B7+E7+H7+K7+N7+Q7+T7 -> 240000 | X7: =C7+F7+I7+L7+O7+R7+U7 -> 100000 | Y7: =W7+X7 -> 340000
A8: OMAR GUERRERO | D8: =B8+C8 -> 0 | G8: =E8+F8 -> 0 | J8: =H8+I8 -> 0 | M8: =K8+L8 -> 0 | P8: =N8+O8 -> 0 | Q8: 185800 | S8: =Q8+R8 -> 185800 | V8: =T8+U8 -> 0 | W8: =B8+E8+H8+K8+N8+Q8+T8 -> 185800 | X8: =C8+F8+I8+L8+O8+R8+U8 -> 0 | Y8: =W8+X8 -> 185800
A9: ALEX Y RAFA | B9: 30000 | C9: 20000 | D9: =B9+C9 -> 50000 | E9: 40000 | F9: 15000 | G9: =E9+F9 -> 55000 | H9: 15000 | I9: 30000 | J9: =H9+I9 -> 45000 | K9: 49999.8 | L9: 39999.8 | M9: =K9+L9 -> 89999.6 | N9: 10000 | O9: 40000 | P9: =N9+O9 -> 50000 | Q9: 20000 | R9: 20000 | S9: =Q9+R9 -> 40000 | T9: 20000 | U9: 30000 | V9: =T9+U9 -> 50000 | W9: =B9+E9+H9+K9+N9+Q9+T9 -> 184999.8 | X9: =C9+F9+I9+L9+O9+R9+U9 -> 194999.8 | Y9: =W9+X9 -> 379999.6
A10: Cristian Ramirez | C10: 25800 | D10: =B10+C10 -> 25800 | E10: 67200 | F10: 45600 | G10: =E10+F10 -> 112800 | I10: 123388.28 | J10: =H10+I10 -> 123388.28 | K10: 28500 | L10: 28500 | M10: =K10+L10 -> 57000 | O10: 57000 | P10: =N10+O10 -> 57000 | S10: =Q10+R10 -> 0 | V10: =T10+U10 -> 0 | W10: =B10+E10+H10+K10+N10+Q10+T10 -> 95700 | X10: =C10+F10+I10+L10+O10+R10+U10 -> 280288.28 | Y10: =W10+X10 -> 375988.28
A11: LALO AGUIRRE | D11: =B11+C11 -> 0 | E11: 22846.25 | F11: 45692.5 | G11: =E11+F11 -> 68538.75 | J11: =H11+I11 -> 0 | K11: 14045.02 | M11: =K11+L11 -> 14045.02 | N11: 6811.7 | P11: =N11+O11 -> 6811.7 | S11: =Q11+R11 -> 0 | V11: =T11+U11 -> 0 | W11: =B11+E11+H11+K11+N11+Q11+T11 -> 43702.97 | X11: =C11+F11+I11+L11+O11+R11+U11 -> 45692.5 | Y11: =W11+X11 -> 89395.47
A12: OMAR | D12: =B12+C12 -> 0 | G12: =E12+F12 -> 0 | H12: 37500 | J12: =H12+I12 -> 37500 | M12: =K12+L12 -> 0 | P12: =N12+O12 -> 0 | S12: =Q12+R12 -> 0 | V12: =T12+U12 -> 0 | W12: =B12+E12+H12+K12+N12+Q12+T12 -> 37500 | X12: =C12+F12+I12+L12+O12+R12+U12 -> 0 | Y12: =W12+X12 -> 37500
A13: NOMINA JACONA | D13: =B13+C13 -> 0 | G13: =E13+F13 -> 0 | J13: =H13+I13 -> 0 | M13: =K13+L13 -> 0 | N13: 21600 | O13: 10800 | P13: =N13+O13 -> 32400 | Q13: 12000 | S13: =Q13+R13 -> 12000 | V13: =T13+U13 -> 0 | W13: =B13+E13+H13+K13+N13+Q13+T13 -> 33600 | X13: =C13+F13+I13+L13+O13+R13+U13 -> 10800 | Y13: =W13+X13 -> 44400
A14: MATERIAL RAISA | D14: =B14+C14 -> 0 | G14: =E14+F14 -> 0 | J14: =H14+I14 -> 0 | M14: =K14+L14 -> 0 | P14: =N14+O14 -> 0 | Q14: 24644.75 | S14: =Q14+R14 -> 24644.75 | V14: =T14+U14 -> 0 | W14: =B14+E14+H14+K14+N14+Q14+T14 -> 24644.75 | X14: =C14+F14+I14+L14+O14+R14+U14 -> 0 | Y14: =W14+X14 -> 24644.75
A15: JOSE "CARAS" EQUIPO REFRIGERACION | D15: =B15+C15 -> 0 | G15: =E15+F15 -> 0 | J15: =H15+I15 -> 0 | M15: =K15+L15 -> 0 | P15: =N15+O15 -> 0 | S15: =Q15+R15 -> 0 | T15: 20000 | V15: =T15+U15 -> 20000 | W15: =B15+E15+H15+K15+N15+Q15+T15 -> 20000 | X15: =C15+F15+I15+L15+O15+R15+U15 -> 0 | Y15: =W15+X15 -> 20000
A16: SR IGNACIO | B16: 20000 | D16: =B16+C16 -> 20000 | G16: =E16+F16 -> 0 | J16: =H16+I16 -> 0 | M16: =K16+L16 -> 0 | P16: =N16+O16 -> 0 | S16: =Q16+R16 -> 0 | V16: =T16+U16 -> 0 | W16: =B16+E16+H16+K16+N16+Q16+T16 -> 20000 | X16: =C16+F16+I16+L16+O16+R16+U16 -> 0 | Y16: =W16+X16 -> 20000
A17: NOMINA JACONA SABADO | D17: =B17+C17 -> 0 | G17: =E17+F17 -> 0 | J17: =H17+I17 -> 0 | M17: =K17+L17 -> 0 | P17: =N17+O17 -> 0 | Q17: 10000 | S17: =Q17+R17 -> 10000 | T17: 9000 | V17: =T17+U17 -> 9000 | W17: =B17+E17+H17+K17+N17+Q17+T17 -> 19000 | X17: =C17+F17+I17+L17+O17+R17+U17 -> 0 | Y17: =W17+X17 -> 19000
A18: NOMINA JACONA MIERCOLES | D18: =B18+C18 -> 0 | G18: =E18+F18 -> 0 | J18: =H18+I18 -> 0 | M18: =K18+L18 -> 0 | P18: =N18+O18 -> 0 | Q18: 15645 | S18: =Q18+R18 -> 15645 | V18: =T18+U18 -> 0 | W18: =B18+E18+H18+K18+N18+Q18+T18 -> 15645 | X18: =C18+F18+I18+L18+O18+R18+U18 -> 0 | Y18: =W18+X18 -> 15645
A19: OMAR nomina | D19: =B19+C19 -> 0 | G19: =E19+F19 -> 0 | H19: 15600 | J19: =H19+I19 -> 15600 | M19: =K19+L19 -> 0 | P19: =N19+O19 -> 0 | S19: =Q19+R19 -> 0 | V19: =T19+U19 -> 0 | W19: =B19+E19+H19+K19+N19+Q19+T19 -> 15600 | X19: =C19+F19+I19+L19+O19+R19+U19 -> 0 | Y19: =W19+X19 -> 15600
A20: LORE | B20: 12006 | C20: 12006 | D20: =B20+C20 -> 24012 | G20: =E20+F20 -> 0 | J20: =H20+I20 -> 0 | M20: =K20+L20 -> 0 | P20: =N20+O20 -> 0 | S20: =Q20+R20 -> 0 | V20: =T20+U20 -> 0 | W20: =B20+E20+H20+K20+N20+Q20+T20 -> 12006 | X20: =C20+F20+I20+L20+O20+R20+U20 -> 12006 | Y20: =W20+X20 -> 24012
A21: NOMINA JACONA Y OCUMICHO SABADO | D21: =B21+C21 -> 0 | G21: =E21+F21 -> 0 | J21: =H21+I21 -> 0 | M21: =K21+L21 -> 0 | P21: =N21+O21 -> 0 | S21: =Q21+R21 -> 0 | T21: 10000 | V21: =T21+U21 -> 10000 | W21: =B21+E21+H21+K21+N21+Q21+T21 -> 10000 | X21: =C21+F21+I21+L21+O21+R21+U21 -> 0 | Y21: =W21+X21 -> 10000
A22: CIRAM | D22: =B22+C22 -> 0 | G22: =E22+F22 -> 0 | J22: =H22+I22 -> 0 | M22: =K22+L22 -> 0 | P22: =N22+O22 -> 0 | Q22: 7590.03 | R22: 7590.02 | S22: =Q22+R22 -> 15180.05 | U22: 6050 | V22: =T22+U22 -> 6050 | W22: =B22+E22+H22+K22+N22+Q22+T22 -> 7590.03 | X22: =C22+F22+I22+L22+O22+R22+U22 -> 13640.02 | Y22: =W22+X22 -> 21230.05
A23: EDUARDO AGUIRRE | D23: =B23+C23 -> 0 | G23: =E23+F23 -> 0 | J23: =H23+I23 -> 0 | M23: =K23+L23 -> 0 | P23: =N23+O23 -> 0 | S23: =Q23+R23 -> 0 | T23: 7508.23 | V23: =T23+U23 -> 7508.23 | W23: =B23+E23+H23+K23+N23+Q23+T23 -> 7508.23 | X23: =C23+F23+I23+L23+O23+R23+U23 -> 0 | Y23: =W23+X23 -> 7508.23
A24: LORE (Transporte Personal) | D24: =B24+C24 -> 0 | E24: 7308 | F24: 25000 | G24: =E24+F24 -> 32308 | I24: 8526 | J24: =H24+I24 -> 8526 | L24: 25578 | M24: =K24+L24 -> 25578 | P24: =N24+O24 -> 0 | R24: 6970 | S24: =Q24+R24 -> 6970 | V24: =T24+U24 -> 0 | W24: =B24+E24+H24+K24+N24+Q24+T24 -> 7308 | X24: =C24+F24+I24+L24+O24+R24+U24 -> 66074 | Y24: =W24+X24 -> 73382
A25: NOMINA JACONA Y OCUMICHO MIERCOLES | D25: =B25+C25 -> 0 | G25: =E25+F25 -> 0 | J25: =H25+I25 -> 0 | M25: =K25+L25 -> 0 | P25: =N25+O25 -> 0 | S25: =Q25+R25 -> 0 | U25: 20000 | V25: =T25+U25 -> 20000 | W25: =B25+E25+H25+K25+N25+Q25+T25 -> 0 | X25: =C25+F25+I25+L25+O25+R25+U25 -> 20000 | Y25: =W25+X25 -> 20000
A26: ROBERTO REYES | C26: 40600 | D26: =B26+C26 -> 40600 | F26: 217291.2 | G26: =E26+F26 -> 217291.2 | J26: =H26+I26 -> 0 | M26: =K26+L26 -> 0 | P26: =N26+O26 -> 0 | S26: =Q26+R26 -> 0 | V26: =T26+U26 -> 0 | W26: =B26+E26+H26+K26+N26+Q26+T26 -> 0 | X26: =C26+F26+I26+L26+O26+R26+U26 -> 257891.2 | Y26: =W26+X26 -> 257891.2
A27: SINDULFO | C27: 40000 | D27: =B27+C27 -> 40000 | F27: 20000 | G27: =E27+F27 -> 20000 | I27: 196991.2 | J27: =H27+I27 -> 196991.2 | L27: 147743.4 | M27: =K27+L27 -> 147743.4 | P27: =N27+O27 -> 0 | S27: =Q27+R27 -> 0 | U27: 49247.8 | V27: =T27+U27 -> 49247.8 | W27: =B27+E27+H27+K27+N27+Q27+T27 -> 0 | X27: =C27+F27+I27+L27+O27+R27+U27 -> 453982.4 | Y27: =W27+X27 -> 453982.4
A28: TRANSPORTE LORE | D28: =B28+C28 -> 0 | G28: =E28+F28 -> 0 | I28: 9570 | J28: =H28+I28 -> 9570 | M28: =K28+L28 -> 0 | P28: =N28+O28 -> 0 | S28: =Q28+R28 -> 0 | V28: =T28+U28 -> 0 | W28: =B28+E28+H28+K28+N28+Q28+T28 -> 0 | X28: =C28+F28+I28+L28+O28+R28+U28 -> 9570 | Y28: =W28+X28 -> 9570
A29: TOTAL NÓMINA/PERSONAL | B29: =SUM(B4:B28) -> 650006 | C29: =SUM(C4:C28) -> 238542 | D29: =SUM(D4:D28) -> 888548 | E29: =SUM(E4:E28) -> 972504.75 | F29: =SUM(F4:F28) -> 518583.7 | G29: =SUM(G4:G28) -> 1491088.4 | H29: =SUM(H4:H28) -> 519300 | I29: =SUM(I4:I28) -> 427925.48 | ... Y29: =SUM(Y4:Y28) -> 7174318.9

Sheet 📊 Empaque-Material
A1: Detalle mensual por concepto — Empaque/Material
A2: Concepto | B2: Nov | E2: Dic | H2: Ene | K2: Feb | N2: Mar | Q2: Abr | T2: May | W2: TOTAL
B3: Pago | C3: Pendiente | D3: Total | E3: Pago | F3: Pendiente | G3: Total | H3: Pago | I3: Pendiente | J3: Total | K3: Pago | L3: Pendiente | M3: Total | N3: Pago | O3: Pendiente | P3: Total | Q3: Pago | R3: Pendiente | S3: Total | T3: Pago | U3: Pendiente | V3: Total | W3: Pago | X3: Pendiente | Y3: Total
A4: PATAGONIA CAJA CARTON y 30 lbs | D4: =B4+C4 -> 0 | G4: =E4+F4 -> 0 | J4: =H4+I4 -> 0 | M4: =K4+L4 -> 0 | P4: =N4+O4 -> 0 | S4: =Q4+R4 -> 0 | T4: 153555 | V4: =T4+U4 -> 153555 | W4: =B4+E4+H4+K4+N4+Q4+T4 -> 153555 | X4: =C4+F4+I4+L4+O4+R4+U4 -> 0 | Y4: =W4+X4 -> 153555
A5: CAJA CARTON (PATAGONIA) 20 y 30 lbs | D5: =B5+C5 -> 0 | G5: =E5+F5 -> 0 | H5: 9802 | J5: =H5+I5 -> 9802 | K5: 19604 | L5: 9802 | M5: =K5+L5 -> 29406 | N5: 1896.6 | O5: 15549.8 | P5: =N5+O5 -> 17446.4 | Q5: 95845 | R5: 9135 | S5: =Q5+R5 -> 104980 | V5: =T5+U5 -> 0 | W5: =B5+E5+H5+K5+N5+Q5+T5 -> 127147.6 | X5: =C5+F5+I5+L5+O5+R5+U5 -> 34486.8 | Y5: =W5+X5 -> 161634.4
A6: CAJA RUTH GDL | D6: =B6+C6 -> 0 | G6: =E6+F6 -> 0 | J6: =H6+I6 -> 0 | K6: 77328.91 | L6: 93280 | M6: =K6+L6 -> 170608.91 | N6: 20000 | O6: 241881.94 | P6: =N6+O6 -> 261881.94 | R6: 61642.4 | S6: =Q6+R6 -> 61642.4 | V6: =T6+U6 -> 0 | W6: =B6+E6+H6+K6+N6+Q6+T6 -> 97328.91 | X6: =C6+F6+I6+L6+O6+R6+U6 -> 396804.34 | Y6: =W6+X6 -> 494133.25
A7: CAJA CARTON (PATAGONIA) | D7: =B7+C7 -> 0 | E7: 58812 | G7: =E7+F7 -> 58812 | H7: 3897.6 | I7: 23144 | J7: =H7+I7 -> 27041.6 | M7: =K7+L7 -> 0 | P7: =N7+O7 -> 0 | S7: =Q7+R7 -> 0 | V7: =T7+U7 -> 0 | W7: =B7+E7+H7+K7+N7+Q7+T7 -> 62709.6 | X7: =C7+F7+I7+L7+O7+R7+U7 -> 23144 | Y7: =W7+X7 -> 85853.6
A8: CAJA RUTH GDLMK BOXES | D8: =B8+C8 -> 0 | G8: =E8+F8 -> 0 | J8: =H8+I8 -> 0 | M8: =K8+L8 -> 0 | P8: =N8+O8 -> 0 | Q8: 61642.4 | R8: 61642.4 | S8: =Q8+R8 -> 123284.8 | V8: =T8+U8 -> 0 | W8: =B8+E8+H8+K8+N8+Q8+T8 -> 61642.4 | X8: =C8+F8+I8+L8+O8+R8+U8 -> 61642.4 | Y8: =W8+X8 -> 123284.8
A9: JOSE HDEZ GARCIA (PAGO TARIMA) | D9: =B9+C9 -> 0 | G9: =E9+F9 -> 0 | J9: =H9+I9 -> 0 | M9: =K9+L9 -> 0 | O9: 15370 | P9: =N9+O9 -> 15370 | Q9: 15370 | R9: 61480 | S9: =Q9+R9 -> 76850 | T9: 30740 | U9: 76850 | V9: =T9+U9 -> 107590 | W9: =B9+E9+H9+K9+N9+Q9+T9 -> 46110 | X9: =C9+F9+I9+L9+O9+R9+U9 -> 153700 | Y9: =W9+X9 -> 199810
A10: BOLSA 30 LBS CHAVINDA | D10: =B10+C10 -> 0 | G10: =E10+F10 -> 0 | I10: 8700 | J10: =H10+I10 -> 8700 | K10: 14500 | L10: 5800 | M10: =K10+L10 -> 20300 | O10: 36250 | P10: =N10+O10 -> 36250 | Q10: 18000 | R10: 14500 | S10: =Q10+R10 -> 32500 | V10: =T10+U10 -> 0 | W10: =B10+E10+H10+K10+N10+Q10+T10 -> 32500 | X10: =C10+F10+I10+L10+O10+R10+U10 -> 65250 | Y10: =W10+X10 -> 97750
A11: Ing Aguilar , embolsadora | B11: 15000 | D11: =B11+C11 -> 15000 | E11: 12000 | F11: 24000 | G11: =E11+F11 -> 36000 | I11: 35178 | J11: =H11+I11 -> 35178 | L11: 70356 | M11: =K11+L11 -> 70356 | P11: =N11+O11 -> 0 | S11: =Q11+R11 -> 0 | V11: =T11+U11 -> 0 | W11: =B11+E11+H11+K11+N11+Q11+T11 -> 27000 | X11: =C11+F11+I11+L11+O11+R11+U11 -> 129534 | Y11: =W11+X11 -> 156534
A12: CAJA PATAGONIA | D12: =B12+C12 -> 0 | G12: =E12+F12 -> 0 | H12: 16800 | J12: =H12+I12 -> 16800 | M12: =K12+L12 -> 0 | P12: =N12+O12 -> 0 | S12: =Q12+R12 -> 0 | V12: =T12+U12 -> 0 | W12: =B12+E12+H12+K12+N12+Q12+T12 -> 16800 | X12: =C12+F12+I12+L12+O12+R12+U12 -> 0 | Y12: =W12+X12 -> 16800
A13: EMBAPACK | D13: =B13+C13 -> 0 | E13: 5000 | G13: =E13+F13 -> 5000 | I13: 2987 | J13: =H13+I13 -> 2987 | K13: 9856.45 | M13: =K13+L13 -> 9856.45 | P13: =N13+O13 -> 0 | S13: =Q13+R13 -> 0 | V13: =T13+U13 -> 0 | W13: =B13+E13+H13+K13+N13+Q13+T13 -> 14856.45 | X13: =C13+F13+I13+L13+O13+R13+U13 -> 2987 | Y13: =W13+X13 -> 17843.45
A14: EMBAPACK Bolsa Verde) | D14: =B14+C14 -> 0 | G14: =E14+F14 -> 0 | J14: =H14+I14 -> 0 | M14: =K14+L14 -> 0 | N14: 1493.5 | O14: 23896 | P14: =N14+O14 -> 25389.5 | Q14: 13310.12 | S14: =Q14+R14 -> 13310.12 | V14: =T14+U14 -> 0 | W14: =B14+E14+H14+K14+N14+Q14+T14 -> 14803.62 | X14: =C14+F14+I14+L14+O14+R14+U14 -> 23896 | Y14: =W14+X14 -> 38699.62
A15: Edgar Joel Vega Martínez (Emplaye) | D15: =B15+C15 -> 0 | G15: =E15+F15 -> 0 | J15: =H15+I15 -> 0 | K15: 2728.32 | M15: =K15+L15 -> 2728.32 | N15: 3410 | P15: =N15+O15 -> 3410 | Q15: 3970.21 | R15: 7940.42 | S15: =Q15+R15 -> 11910.63 | T15: 4235.94 | U15: 24389.07 | V15: =T15+U15 -> 28625.01 | W15: =B15+E15+H15+K15+N15+Q15+T15 -> 14344.47 | X15: =C15+F15+I15+L15+O15+R15+U15 -> 32329.49 | Y15: =W15+X15 -> 46673.96
A16: EMBAPACK Bolsa AZUL | D16: =B16+C16 -> 0 | G16: =E16+F16 -> 0 | J16: =H16+I16 -> 0 | M16: =K16+L16 -> 0 | P16: =N16+O16 -> 0 | Q16: 7222 | S16: =Q16+R16 -> 7222 | T16: 6666.98 | V16: =T16+U16 -> 6666.98 | W16: =B16+E16+H16+K16+N16+Q16+T16 -> 13888.98 | X16: =C16+F16+I16+L16+O16+R16+U16 -> 0 | Y16: =W16+X16 -> 13888.98
A17: EMBAPACK Bolsa Verde | D17: =B17+C17 -> 0 | G17: =E17+F17 -> 0 | J17: =H17+I17 -> 0 | M17: =K17+L17 -> 0 | P17: =N17+O17 -> 0 | Q17: 10788 | S17: =Q17+R17 -> 10788 | V17: =T17+U17 -> 0 | W17: =B17+E17+H17+K17+N17+Q17+T17 -> 10788 | X17: =C17+F17+I17+L17+O17+R17+U17 -> 0 | Y17: =W17+X17 -> 10788
A18: CIELO (TARIMAS) | C18: 16240 | D18: =B18+C18 -> 16240 | E18: 8120 | G18: =E18+F18 -> 8120 | I18: 31900 | J18: =H18+I18 -> 31900 | M18: =K18+L18 -> 0 | P18: =N18+O18 -> 0 | S18: =Q18+R18 -> 0 | V18: =T18+U18 -> 0 | W18: =B18+E18+H18+K18+N18+Q18+T18 -> 8120 | X18: =C18+F18+I18+L18+O18+R18+U18 -> 48140 | Y18: =W18+X18 -> 56260
A19: Bolsa Transparente (Chavinda) | D19: =B19+C19 -> 0 | E19: 8000 | F19: 30050 | G19: =E19+F19 -> 38050 | J19: =H19+I19 -> 0 | M19: =K19+L19 -> 0 | P19: =N19+O19 -> 0 | S19: =Q19+R19 -> 0 | V19: =T19+U19 -> 0 | W19: =B19+E19+H19+K19+N19+Q19+T19 -> 8000 | X19: =C19+F19+I19+L19+O19+R19+U19 -> 30050 | Y19: =W19+X19 -> 38050
A20: EMBAPACK Bolsa AZUL) | D20: =B20+C20 -> 0 | G20: =E20+F20 -> 0 | J20: =H20+I20 -> 0 | M20: =K20+L20 -> 0 | P20: =N20+O20 -> 0 | S20: =Q20+R20 -> 0 | T20: 7192 | V20: =T20+U20 -> 7192 | W20: =B20+E20+H20+K20+N20+Q20+T20 -> 7192 | X20: =C20+F20+I20+L20+O20+R20+U20 -> 0 | Y20: =W20+X20 -> 7192
A21: EMBAPACK Bolsa TRNASPARENTE | D21: =B21+C21 -> 0 | G21: =E21+F21 -> 0 | J21: =H21+I21 -> 0 | M21: =K21+L21 -> 0 | P21: =N21+O21 -> 0 | S21: =Q21+R21 -> 0 | T21: 7134 | V21: =T21+U21 -> 7134 | W21: =B21+E21+H21+K21+N21+Q21+T21 -> 7134 | X21: =C21+F21+I21+L21+O21+R21+U21 -> 0 | Y21: =W21+X21 -> 7134
A22: CODICE ETIQUETAS | D22: =B22+C22 -> 0 | G22: =E22+F22 -> 0 | J22: =H22+I22 -> 0 | M22: =K22+L22 -> 0 | P22: =N22+O22 -> 0 | S22: =Q22+R22 -> 0 | T22: 4172.11 | U22: 7193.3 | V22: =T22+U22 -> 11365.41 | W22: =B22+E22+H22+K22+N22+Q22+T22 -> 4172.11 | X22: =C22+F22+I22+L22+O22+R22+U22 -> 7193.3 | Y22: =W22+X22 -> 11365.41
A23: CODICE | D23: =B23+C23 -> 0 | G23: =E23+F23 -> 0 | H23: 3981.94 | J23: =H23+I23 -> 3981.94 | M23: =K23+L23 -> 0 | P23: =N23+O23 -> 0 | S23: =Q23+R23 -> 0 | V23: =T23+U23 -> 0 | W23: =B23+E23+H23+K23+N23+Q23+T23 -> 3981.94 | X23: =C23+F23+I23+L23+O23+R23+U23 -> 0 | Y23: =W23+X23 -> 3981.94
A24: ETIQUETAS CODICE | D24: =B24+C24 -> 0 | E24: 3648.39 | G24: =E24+F24 -> 3648.39 | J24: =H24+I24 -> 0 | M24: =K24+L24 -> 0 | P24: =N24+O24 -> 0 | S24: =Q24+R24 -> 0 | V24: =T24+U24 -> 0 | W24: =B24+E24+H24+K24+N24+Q24+T24 -> 3648.39 | X24: =C24+F24+I24+L24+O24+R24+U24 -> 0 | Y24: =W24+X24 -> 3648.39
A25: ETIQUETAS | D25: =B25+C25 -> 0 | G25: =E25+F25 -> 0 | J25: =H25+I25 -> 0 | M25: =K25+L25 -> 0 | N25: 2868 | O25: 2868 | P25: =N25+O25 -> 5736 | S25: =Q25+R25 -> 0 | V25: =T25+U25 -> 0 | W25: =B25+E25+H25+K25+N25+Q25+T25 -> 2868 | X25: =C25+F25+I25+L25+O25+R25+U25 -> 2868 | Y25: =W25+X25 -> 5736
A26: EMBAPACK Bolsa AZUL y verde | D26: =B26+C26 -> 0 | G26: =E26+F26 -> 0 | J26: =H26+I26 -> 0 | M26: =K26+L26 -> 0 | P26: =N26+O26 -> 0 | S26: =Q26+R26 -> 0 | T26: 1783 | V26: =T26+U26 -> 1783 | W26: =B26+E26+H26+K26+N26+Q26+T26 -> 1783 | X26: =C26+F26+I26+L26+O26+R26+U26 -> 0 | Y26: =W26+X26 -> 1783
A27: Aceros Gutz | D27: =B27+C27 -> 0 | G27: =E27+F27 -> 0 | J27: =H27+I27 -> 0 | M27: =K27+L27 -> 0 | P27: =N27+O27 -> 0 | Q27: 1076 | S27: =Q27+R27 -> 1076 | V27: =T27+U27 -> 0 | W27: =B27+E27+H27+K27+N27+Q27+T27 -> 1076 | X27: =C27+F27+I27+L27+O27+R27+U27 -> 0 | Y27: =W27+X27 -> 1076
A28: FLEJE MONTERREY | D28: =B28+C28 -> 0 | G28: =E28+F28 -> 0 | J28: =H28+I28 -> 0 | M28: =K28+L28 -> 0 | P28: =N28+O28 -> 0 | Q28: 600 | S28: =Q28+R28 -> 600 | V28: =T28+U28 -> 0 | W28: =B28+E28+H28+K28+N28+Q28+T28 -> 600 | X28: =C28+F28+I28+L28+O28+R28+U28 -> 0 | Y28: =W28+X28 -> 600
A29: Bolsa (Chavinda) | D29: =B29+C29 -> 0 | G29: =E29+F29 -> 0 | I29: 8460.6 | J29: =H29+I29 -> 8460.6 | M29: =K29+L29 -> 0 | P29: =N29+O29 -> 0 | S29: =Q29+R29 -> 0 | V29: =T29+U29 -> 0 | W29: =B29+E29+H29+K29+N29+Q29+T29 -> 0 | X29: =C29+F29+I29+L29+O29+R29+U29 -> 8460.6 | Y29: =W29+X29 -> 8460.6
A30: CIELO ALEJANDRA (TARIMAS) GONZALO | D30: =B30+C30 -> 0 | G30: =E30+F30 -> 0 | J30: =H30+I30 -> 0 | M30: =K30+L30 -> 0 | P30: =N30+O30 -> 0 | R30: 64960 | S30: =Q30+R30 -> 64960 | U30: 129920 | V30: =T30+U30 -> 129920 | W30: =B30+E30+H30+K30+N30+Q30+T30 -> 0 | X30: =C30+F30+I30+L30+O30+R30+U30 -> 194880 | Y30: =W30+X30 -> 194880
A31: CAJA CARTON (RUTH) | D31: =B31+C31 -> 0 | G31: =E31+F31 -> 0 | I31: 20000 | J31: =H31+I31 -> 20000 | M31: =K31+L31 -> 0 | P31: =N31+O31 -> 0 | S31: =Q31+R31 -> 0 | V31: =T31+U31 -> 0 | W31: =B31+E31+H31+K31+N31+Q31+T31 -> 0 | X31: =C31+F31+I31+L31+O31+R31+U31 -> 20000 | Y31: =W31+X31 -> 20000
A32: CAJA PATAGONI Y EMBAPACK | D32: =B32+C32 -> 0 | G32: =E32+F32 -> 0 | I32: 15000 | J32: =H32+I32 -> 15000 | M32: =K32+L32 -> 0 | P32: =N32+O32 -> 0 | S32: =Q32+R32 -> 0 | V32: =T32+U32 -> 0 | W32: =B32+E32+H32+K32+N32+Q32+T32 -> 0 | X32: =C32+F32+I32+L32+O32+R32+U32 -> 15000 | Y32: =W32+X32 -> 15000
A33: TARIMA | C33: 32480 | D33: =B33+C33 -> 32480 | G33: =E33+F33 -> 0 | J33: =H33+I33 -> 0 | M33: =K33+L33 -> 0 | P33: =N33+O33 -> 0 | S33: =Q33+R33 -> 0 | V33: =T33+U33 -> 0 | W33: =B33+E33+H33+K33+N33+Q33+T33 -> 0 | X33: =C33+F33+I33+L33+O33+R33+U33 -> 32480 | Y33: =W33+X33 -> 32480
A34: TOTAL EMPAQUE/MATERIAL | B34: =SUM(B4:B33) -> 15000 | C34: =SUM(C4:C33) -> 48720 | D34: =SUM(D4:D33) -> 63720 | E34: =SUM(E4:E33) -> 95580.39 | F34: =SUM(F4:F33) -> 54050 | G34: =SUM(G4:G33) -> 149630.39 | H34: =SUM(H4:H33) -> 34481.54 | I34: =SUM(I4:I33) -> 145369.6 | ... Y34: =SUM(Y4:Y33) -> 2024896.4

Sheet 📊 Otros
A1: Detalle mensual por concepto — Otros
A2: Concepto | B2: Nov | E2: Dic | H2: Ene | K2: Feb | N2: Mar | Q2: Abr | T2: May | W2: TOTAL
B3: Pago | C3: Pendiente | D3: Total | E3: Pago | F3: Pendiente | G3: Total | H3: Pago | I3: Pendiente | J3: Total | K3: Pago | L3: Pendiente | M3: Total | N3: Pago | O3: Pendiente | P3: Total | Q3: Pago | R3: Pendiente | S3: Total | T3: Pago | U3: Pendiente | V3: Total | W3: Pago | X3: Pendiente | Y3: Total
A4: AVV (PAGO SANTANDER) | D4: =B4+C4 -> 0 | E4: 280000 | F4: 85000 | G4: =E4+F4 -> 365000 | J4: =H4+I4 -> 0 | M4: =K4+L4 -> 0 | P4: =N4+O4 -> 0 | S4: =Q4+R4 -> 0 | V4: =T4+U4 -> 0 | W4: =B4+E4+H4+K4+N4+Q4+T4 -> 280000 | X4: =C4+F4+I4+L4+O4+R4+U4 -> 85000 | Y4: =W4+X4 -> 365000
A5: AVV (PAGO MONARCA) | D5: =B5+C5 -> 0 | E5: 260435 | G5: =E5+F5 -> 260435 | J5: =H5+I5 -> 0 | M5: =K5+L5 -> 0 | P5: =N5+O5 -> 0 | S5: =Q5+R5 -> 0 | V5: =T5+U5 -> 0 | W5: =B5+E5+H5+K5+N5+Q5+T5 -> 260435 | X5: =C5+F5+I5+L5+O5+R5+U5 -> 0 | Y5: =W5+X5 -> 260435
A6: AVV (PAGO SANTANDERT) | D6: =B6+C6 -> 0 | E6: 83200 | G6: =E6+F6 -> 83200 | J6: =H6+I6 -> 0 | M6: =K6+L6 -> 0 | P6: =N6+O6 -> 0 | S6: =Q6+R6 -> 0 | V6: =T6+U6 -> 0 | W6: =B6+E6+H6+K6+N6+Q6+T6 -> 83200 | X6: =C6+F6+I6+L6+O6+R6+U6 -> 0 | Y6: =W6+X6 -> 83200
A7: Alejandro Rodriguez | D7: =B7+C7 -> 0 | G7: =E7+F7 -> 0 | J7: =H7+I7 -> 0 | K7: 20000 | M7: =K7+L7 -> 20000 | N7: 40000 | O7: 20000 | P7: =N7+O7 -> 60000 | S7: =Q7+R7 -> 0 | V7: =T7+U7 -> 0 | W7: =B7+E7+H7+K7+N7+Q7+T7 -> 60000 | X7: =C7+F7+I7+L7+O7+R7+U7 -> 20000 | Y7: =W7+X7 -> 80000
A8: AVV (MONARCA) | D8: =B8+C8 -> 0 | G8: =E8+F8 -> 0 | J8: =H8+I8 -> 0 | M8: =K8+L8 -> 0 | N8: 50000 | O8: 50000 | P8: =N8+O8 -> 100000 | R8: 50000 | S8: =Q8+R8 -> 50000 | V8: =T8+U8 -> 0 | W8: =B8+E8+H8+K8+N8+Q8+T8 -> 50000 | X8: =C8+F8+I8+L8+O8+R8+U8 -> 100000 | Y8: =W8+X8 -> 150000
A9: TRAMITES CFE | D9: =B9+C9 -> 0 | G9: =E9+F9 -> 0 | J9: =H9+I9 -> 0 | M9: =K9+L9 -> 0 | N9: 14500 | P9: =N9+O9 -> 14500 | S9: =Q9+R9 -> 0 | V9: =T9+U9 -> 0 | W9: =B9+E9+H9+K9+N9+Q9+T9 -> 14500 | X9: =C9+F9+I9+L9+O9+R9+U9 -> 0 | Y9: =W9+X9 -> 14500
A10: AVV MONARCA | D10: =B10+C10 -> 0 | G10: =E10+F10 -> 0 | J10: =H10+I10 -> 0 | L10: 15000 | M10: =K10+L10 -> 15000 | P10: =N10+O10 -> 0 | S10: =Q10+R10 -> 0 | T10: 11000 | V10: =T10+U10 -> 11000 | W10: =B10+E10+H10+K10+N10+Q10+T10 -> 11000 | X10: =C10+F10+I10+L10+O10+R10+U10 -> 15000 | Y10: =W10+X10 -> 26000
A11: CONTRATO REIMER (Lic Carlos) | D11: =B11+C11 -> 0 | E11: 9280 | G11: =E11+F11 -> 9280 | J11: =H11+I11 -> 0 | M11: =K11+L11 -> 0 | P11: =N11+O11 -> 0 | S11: =Q11+R11 -> 0 | V11: =T11+U11 -> 0 | W11: =B11+E11+H11+K11+N11+Q11+T11 -> 9280 | X11: =C11+F11+I11+L11+O11+R11+U11 -> 0 | Y11: =W11+X11 -> 9280
A12: FRENOS CAMIONETA JESUS | D12: =B12+C12 -> 0 | G12: =E12+F12 -> 0 | J12: =H12+I12 -> 0 | M12: =K12+L12 -> 0 | N12: 8120 | P12: =N12+O12 -> 8120 | S12: =Q12+R12 -> 0 | V12: =T12+U12 -> 0 | W12: =B12+E12+H12+K12+N12+Q12+T12 -> 8120 | X12: =C12+F12+I12+L12+O12+R12+U12 -> 0 | Y12: =W12+X12 -> 8120
A13: VERIFICACION FLOSOL | D13: =B13+C13 -> 0 | G13: =E13+F13 -> 0 | J13: =H13+I13 -> 0 | K13: 8000 | M13: =K13+L13 -> 8000 | P13: =N13+O13 -> 0 | S13: =Q13+R13 -> 0 | V13: =T13+U13 -> 0 | W13: =B13+E13+H13+K13+N13+Q13+T13 -> 8000 | X13: =C13+F13+I13+L13+O13+R13+U13 -> 0 | Y13: =W13+X13 -> 8000
A14: ROCIO IMPI | D14: =B14+C14 -> 0 | G14: =E14+F14 -> 0 | J14: =H14+I14 -> 0 | M14: =K14+L14 -> 0 | N14: 7540 | P14: =N14+O14 -> 7540 | S14: =Q14+R14 -> 0 | V14: =T14+U14 -> 0 | W14: =B14+E14+H14+K14+N14+Q14+T14 -> 7540 | X14: =C14+F14+I14+L14+O14+R14+U14 -> 0 | Y14: =W14+X14 -> 7540
A15: COMPRA LAPTOP | D15: =B15+C15 -> 0 | G15: =E15+F15 -> 0 | J15: =H15+I15 -> 0 | M15: =K15+L15 -> 0 | N15: 7499 | P15: =N15+O15 -> 7499 | S15: =Q15+R15 -> 0 | V15: =T15+U15 -> 0 | W15: =B15+E15+H15+K15+N15+Q15+T15 -> 7499 | X15: =C15+F15+I15+L15+O15+R15+U15 -> 0 | Y15: =W15+X15 -> 7499
A16: AVV | D16: =B16+C16 -> 0 | G16: =E16+F16 -> 0 | J16: =H16+I16 -> 0 | K16: 6500 | L16: 6500 | M16: =K16+L16 -> 13000 | P16: =N16+O16 -> 0 | S16: =Q16+R16 -> 0 | V16: =T16+U16 -> 0 | W16: =B16+E16+H16+K16+N16+Q16+T16 -> 6500 | X16: =C16+F16+I16+L16+O16+R16+U16 -> 6500 | Y16: =W16+X16 -> 13000
A17: PAGO CONTPAQ | D17: =B17+C17 -> 0 | E17: 6020.4 | G17: =E17+F17 -> 6020.4 | J17: =H17+I17 -> 0 | M17: =K17+L17 -> 0 | P17: =N17+O17 -> 0 | S17: =Q17+R17 -> 0 | V17: =T17+U17 -> 0 | W17: =B17+E17+H17+K17+N17+Q17+T17 -> 6020.4 | X17: =C17+F17+I17+L17+O17+R17+U17 -> 0 | Y17: =W17+X17 -> 6020.4
A18: BATAS, DIESEL, HOMEDEPOT | D18: =B18+C18 -> 0 | G18: =E18+F18 -> 0 | J18: =H18+I18 -> 0 | M18: =K18+L18 -> 0 | P18: =N18+O18 -> 0 | S18: =Q18+R18 -> 0 | T18: 4674 | V18: =T18+U18 -> 4674 | W18: =B18+E18+H18+K18+N18+Q18+T18 -> 4674 | X18: =C18+F18+I18+L18+O18+R18+U18 -> 0 | Y18: =W18+X18 -> 4674
A19: SAM JARABES TAPATIOS | D19: =B19+C19 -> 0 | G19: =E19+F19 -> 0 | J19: =H19+I19 -> 0 | M19: =K19+L19 -> 0 | P19: =N19+O19 -> 0 | Q19: 3888 | S19: =Q19+R19 -> 3888 | V19: =T19+U19 -> 0 | W19: =B19+E19+H19+K19+N19+Q19+T19 -> 3888 | X19: =C19+F19+I19+L19+O19+R19+U19 -> 0 | Y19: =W19+X19 -> 3888
A20: DIKEN | D20: =B20+C20 -> 0 | G20: =E20+F20 -> 0 | H20: 2041.71 | J20: =H20+I20 -> 2041.71 | M20: =K20+L20 -> 0 | P20: =N20+O20 -> 0 | Q20: 1441.56 | R20: 1186.36 | S20: =Q20+R20 -> 2627.92 | U20: 6099 | V20: =T20+U20 -> 6099 | W20: =B20+E20+H20+K20+N20+Q20+T20 -> 3483.27 | X20: =C20+F20+I20+L20+O20+R20+U20 -> 7285.36 | Y20: =W20+X20 -> 10768.63
A21: Pintura FV ( cubeta Esmalte) | D21: =B21+C21 -> 0 | G21: =E21+F21 -> 0 | J21: =H21+I21 -> 0 | M21: =K21+L21 -> 0 | P21: =N21+O21 -> 0 | Q21: 3310 | S21: =Q21+R21 -> 3310 | V21: =T21+U21 -> 0 | W21: =B21+E21+H21+K21+N21+Q21+T21 -> 3310 | X21: =C21+F21+I21+L21+O21+R21+U21 -> 0 | Y21: =W21+X21 -> 3310
A22: PAGO BOTELLA PLASTICO 1 LTO | D22: =B22+C22 -> 0 | G22: =E22+F22 -> 0 | J22: =H22+I22 -> 0 | M22: =K22+L22 -> 0 | N22: 2501.41 | P22: =N22+O22 -> 2501.41 | S22: =Q22+R22 -> 0 | V22: =T22+U22 -> 0 | W22: =B22+E22+H22+K22+N22+Q22+T22 -> 2501.41 | X22: =C22+F22+I22+L22+O22+R22+U22 -> 0 | Y22: =W22+X22 -> 2501.41
A23: MARACUYA BORREGOS | D23: =B23+C23 -> 0 | G23: =E23+F23 -> 0 | J23: =H23+I23 -> 0 | K23: 2400 | M23: =K23+L23 -> 2400 | P23: =N23+O23 -> 0 | S23: =Q23+R23 -> 0 | V23: =T23+U23 -> 0 | W23: =B23+E23+H23+K23+N23+Q23+T23 -> 2400 | X23: =C23+F23+I23+L23+O23+R23+U23 -> 0 | Y23: =W23+X23 -> 2400
A24: MARACUYA | D24: =B24+C24 -> 0 | G24: =E24+F24 -> 0 | J24: =H24+I24 -> 0 | M24: =K24+L24 -> 0 | N24: 2400 | P24: =N24+O24 -> 2400 | S24: =Q24+R24 -> 0 | V24: =T24+U24 -> 0 | W24: =B24+E24+H24+K24+N24+Q24+T24 -> 2400 | X24: =C24+F24+I24+L24+O24+R24+U24 -> 0 | Y24: =W24+X24 -> 2400
A25: STEREN NEBULIZADORES | D25: =B25+C25 -> 0 | G25: =E25+F25 -> 0 | J25: =H25+I25 -> 0 | M25: =K25+L25 -> 0 | P25: =N25+O25 -> 0 | S25: =Q25+R25 -> 0 | T25: 1551 | V25: =T25+U25 -> 1551 | W25: =B25+E25+H25+K25+N25+Q25+T25 -> 1551 | X25: =C25+F25+I25+L25+O25+R25+U25 -> 0 | Y25: =W25+X25 -> 1551
A26: CHRISTIAN MANUEL (TAMINAS) | D26: =B26+C26 -> 0 | G26: =E26+F26 -> 0 | J26: =H26+I26 -> 0 | M26: =K26+L26 -> 0 | P26: =N26+O26 -> 0 | S26: =Q26+R26 -> 0 | T26: 1044 | V26: =T26+U26 -> 1044 | W26: =B26+E26+H26+K26+N26+Q26+T26 -> 1044 | X26: =C26+F26+I26+L26+O26+R26+U26 -> 0 | Y26: =W26+X26 -> 1044
A27: Varios (Llaves reparacion FV) | D27: =B27+C27 -> 0 | G27: =E27+F27 -> 0 | J27: =H27+I27 -> 0 | M27: =K27+L27 -> 0 | P27: =N27+O27 -> 0 | Q27: 520 | S27: =Q27+R27 -> 520 | V27: =T27+U27 -> 0 | W27: =B27+E27+H27+K27+N27+Q27+T27 -> 520 | X27: =C27+F27+I27+L27+O27+R27+U27 -> 0 | Y27: =W27+X27 -> 520
A28: DELFIN | D28: =B28+C28 -> 0 | G28: =E28+F28 -> 0 | I28: 246.44 | J28: =H28+I28 -> 246.44 | M28: =K28+L28 -> 0 | P28: =N28+O28 -> 0 | S28: =Q28+R28 -> 0 | V28: =T28+U28 -> 0 | W28: =B28+E28+H28+K28+N28+Q28+T28 -> 0 | X28: =C28+F28+I28+L28+O28+R28+U28 -> 246.44 | Y28: =W28+X28 -> 246.44
A29: EFECTIVO | C29: 20000 | D29: =B29+C29 -> 20000 | G29: =E29+F29 -> 0 | J29: =H29+I29 -> 0 | M29: =K29+L29 -> 0 | P29: =N29+O29 -> 0 | S29: =Q29+R29 -> 0 | V29: =T29+U29 -> 0 | W29: =B29+E29+H29+K29+N29+Q29+T29 -> 0 | X29: =C29+F29+I29+L29+O29+R29+U29 -> 20000 | Y29: =W29+X29 -> 20000
A30: MK BOXES RUTH GDL | D30: =B30+C30 -> 0 | G30: =E30+F30 -> 0 | J30: =H30+I30 -> 0 | M30: =K30+L30 -> 0 | P30: =N30+O30 -> 0 | S30: =Q30+R30 -> 0 | U30: 253216.55 | V30: =T30+U30 -> 253216.55 | W30: =B30+E30+H30+K30+N30+Q30+T30 -> 0 | X30: =C30+F30+I30+L30+O30+R30+U30 -> 253216.55 | Y30: =W30+X30 -> 253216.55
A31: PROLIZA | D31: =B31+C31 -> 0 | G31: =E31+F31 -> 0 | I31: 593.5 | J31: =H31+I31 -> 593.5 | M31: =K31+L31 -> 0 | P31: =N31+O31 -> 0 | S31: =Q31+R31 -> 0 | V31: =T31+U31 -> 0 | W31: =B31+E31+H31+K31+N31+Q31+T31 -> 0 | X31: =C31+F31+I31+L31+O31+R31+U31 -> 593.5 | Y31: =W31+X31 -> 593.5
A32: SEGURO AVEO | D32: =B32+C32 -> 0 | G32: =E32+F32 -> 0 | J32: =H32+I32 -> 0 | L32: 2028.84 | M32: =K32+L32 -> 2028.84 | P32: =N32+O32 -> 0 | S32: =Q32+R32 -> 0 | V32: =T32+U32 -> 0 | W32: =B32+E32+H32+K32+N32+Q32+T32 -> 0 | X32: =C32+F32+I32+L32+O32+R32+U32 -> 2028.84 | Y32: =W32+X32 -> 2028.84
A33: Transporte de Gente | D33: =B33+C33 -> 0 | F33: 12000 | G33: =E33+F33 -> 12000 | J33: =H33+I33 -> 0 | M33: =K33+L33 -> 0 | P33: =N33+O33 -> 0 | S33: =Q33+R33 -> 0 | V33: =T33+U33 -> 0 | W33: =B33+E33+H33+K33+N33+Q33+T33 -> 0 | X33: =C33+F33+I33+L33+O33+R33+U33 -> 12000 | Y33: =W33+X33 -> 12000
A34: gastos | D34: =B34+C34 -> 0 | G34: =E34+F34 -> 0 | I34: 10000 | J34: =H34+I34 -> 10000 | M34: =K34+L34 -> 0 | P34: =N34+O34 -> 0 | S34: =Q34+R34 -> 0 | V34: =T34+U34 -> 0 | W34: =B34+E34+H34+K34+N34+Q34+T34 -> 0 | X34: =C34+F34+I34+L34+O34+R34+U34 -> 10000 | Y34: =W34+X34 -> 10000
A35: TOTAL OTROS | B35: =SUM(B4:B34) -> 0 | C35: =SUM(C4:C34) -> 20000 | D35: =SUM(D4:D34) -> 20000 | E35: =SUM(E4:E34) -> 638935.4 | F35: =SUM(F4:F34) -> 97000 | G35: =SUM(G4:G34) -> 735935.4 | H35: =SUM(H4:H34) -> 2041.71 | I35: =SUM(I4:I34) -> 10839.94 | ... Y35: =SUM(Y4:Y34) -> 1369736.8

Sheet 📊 Servicios
A1: Detalle mensual por concepto — Servicios
A2: Concepto | B2: Nov | E2: Dic | H2: Ene | K2: Feb | N2: Mar | Q2: Abr | T2: May | W2: TOTAL
B3: Pago | C3: Pendiente | D3: Total | E3: Pago | F3: Pendiente | G3: Total | H3: Pago | I3: Pendiente | J3: Total | K3: Pago | L3: Pendiente | M3: Total | N3: Pago | O3: Pendiente | P3: Total | Q3: Pago | R3: Pendiente | S3: Total | T3: Pago | U3: Pendiente | V3: Total | W3: Pago | X3: Pendiente | Y3: Total
A4: Honorarios contador | D4: =B4+C4 -> 0 | E4: 9588.28 | F4: 19176.56 | G4: =E4+F4 -> 28764.84 | H4: 19858.96 | I4: 17802 | J4: =H4+I4 -> 37660.96 | K4: 16218.6 | M4: =K4+L4 -> 16218.6 | N4: 29133.384 | O4: 2940 | P4: =N4+O4 -> 32073.384 | Q4: 30206.19 | S4: =Q4+R4 -> 30206.19 | T4: 41095.404 | V4: =T4+U4 -> 41095.404 | W4: =B4+E4+H4+K4+N4+Q4+T4 -> 146100.82 | X4: =C4+F4+I4+L4+O4+R4+U4 -> 39918.56 | Y4: =W4+X4 -> 186019.38
A5: DEPACHO GARNICA | B5: 18000 | C5: 9000 | D5: =B5+C5 -> 27000 | F5: 27000 | G5: =E5+F5 -> 27000 | J5: =H5+I5 -> 0 | M5: =K5+L5 -> 0 | P5: =N5+O5 -> 0 | Q5: 8952.3 | S5: =Q5+R5 -> 8952.3 | T5: 8952.3 | U5: 8952.3 | V5: =T5+U5 -> 17904.6 | W5: =B5+E5+H5+K5+N5+Q5+T5 -> 35904.6 | X5: =C5+F5+I5+L5+O5+R5+U5 -> 44952.3 | Y5: =W5+X5 -> 80856.9
A6: CIPSA | B6: 6000 | C6: 3000 | D6: =B6+C6 -> 9000 | E6: 8352 | F6: 14136 | G6: =E6+F6 -> 22488 | J6: =H6+I6 -> 0 | M6: =K6+L6 -> 0 | N6: 3828 | P6: =N6+O6 -> 3828 | Q6: 5568 | R6: 5568 | S6: =Q6+R6 -> 11136 | U6: 7772 | V6: =T6+U6 -> 7772 | W6: =B6+E6+H6+K6+N6+Q6+T6 -> 23748 | X6: =C6+F6+I6+L6+O6+R6+U6 -> 30476 | Y6: =W6+X6 -> 54224
A7: GLADYS (CERTIFICACION) | D7: =B7+C7 -> 0 | G7: =E7+F7 -> 0 | J7: =H7+I7 -> 0 | M7: =K7+L7 -> 0 | P7: =N7+O7 -> 0 | Q7: 14500 | R7: 30000 | S7: =Q7+R7 -> 44500 | U7: 15000 | V7: =T7+U7 -> 15000 | W7: =B7+E7+H7+K7+N7+Q7+T7 -> 14500 | X7: =C7+F7+I7+L7+O7+R7+U7 -> 45000 | Y7: =W7+X7 -> 59500
A8: telefono | D8: =B8+C8 -> 0 | E8: 12000 | G8: =E8+F8 -> 12000 | J8: =H8+I8 -> 0 | M8: =K8+L8 -> 0 | P8: =N8+O8 -> 0 | S8: =Q8+R8 -> 0 | V8: =T8+U8 -> 0 | W8: =B8+E8+H8+K8+N8+Q8+T8 -> 12000 | X8: =C8+F8+I8+L8+O8+R8+U8 -> 0 | Y8: =W8+X8 -> 12000
A9: Primus Lab | D9: =B9+C9 -> 0 | E9: 3014.2 | G9: =E9+F9 -> 3014.2 | J9: =H9+I9 -> 0 | M9: =K9+L9 -> 0 | P9: =N9+O9 -> 0 | Q9: 2277.13 | S9: =Q9+R9 -> 2277.13 | T9: 6086.26 | U9: 6086.26 | V9: =T9+U9 -> 12172.52 | W9: =B9+E9+H9+K9+N9+Q9+T9 -> 11377.59 | X9: =C9+F9+I9+L9+O9+R9+U9 -> 6086.26 | Y9: =W9+X9 -> 17463.85
A10: Contador Carlos | D10: =B10+C10 -> 0 | E10: 10000 | G10: =E10+F10 -> 10000 | J10: =H10+I10 -> 0 | M10: =K10+L10 -> 0 | P10: =N10+O10 -> 0 | S10: =Q10+R10 -> 0 | V10: =T10+U10 -> 0 | W10: =B10+E10+H10+K10+N10+Q10+T10 -> 10000 | X10: =C10+F10+I10+L10+O10+R10+U10 -> 0 | Y10: =W10+X10 -> 10000
A11: SANICHEM | D11: =B11+C11 -> 0 | G11: =E11+F11 -> 0 | I11: 12396.2 | J11: =H11+I11 -> 12396.2 | M11: =K11+L11 -> 0 | P11: =N11+O11 -> 0 | R11: 14250.6 | S11: =Q11+R11 -> 14250.6 | T11: 6042.2 | V11: =T11+U11 -> 6042.2 | W11: =B11+E11+H11+K11+N11+Q11+T11 -> 6042.2 | X11: =C11+F11+I11+L11+O11+R11+U11 -> 26646.8 | Y11: =W11+X11 -> 32689
A12: IMPRENTA BERNARDO | D12: =B12+C12 -> 0 | G12: =E12+F12 -> 0 | J12: =H12+I12 -> 0 | M12: =K12+L12 -> 0 | P12: =N12+O12 -> 0 | Q12: 2900 | S12: =Q12+R12 -> 2900 | V12: =T12+U12 -> 0 | W12: =B12+E12+H12+K12+N12+Q12+T12 -> 2900 | X12: =C12+F12+I12+L12+O12+R12+U12 -> 0 | Y12: =W12+X12 -> 2900
A13: TRES GUERRAS | D13: =B13+C13 -> 0 | G13: =E13+F13 -> 0 | J13: =H13+I13 -> 0 | M13: =K13+L13 -> 0 | P13: =N13+O13 -> 0 | Q13: 2516.21 | S13: =Q13+R13 -> 2516.21 | V13: =T13+U13 -> 0 | W13: =B13+E13+H13+K13+N13+Q13+T13 -> 2516.21 | X13: =C13+F13+I13+L13+O13+R13+U13 -> 0 | Y13: =W13+X13 -> 2516.21
A14: Contador Reymundo | D14: =B14+C14 -> 0 | E14: 2000 | G14: =E14+F14 -> 2000 | J14: =H14+I14 -> 0 | M14: =K14+L14 -> 0 | P14: =N14+O14 -> 0 | S14: =Q14+R14 -> 0 | V14: =T14+U14 -> 0 | W14: =B14+E14+H14+K14+N14+Q14+T14 -> 2000 | X14: =C14+F14+I14+L14+O14+R14+U14 -> 0 | Y14: =W14+X14 -> 2000
A15: DEPACHO GARNICA (Pago Febrero 2026) | D15: =B15+C15 -> 0 | G15: =E15+F15 -> 0 | J15: =H15+I15 -> 0 | M15: =K15+L15 -> 0 | P15: =N15+O15 -> 0 | S15: =Q15+R15 -> 0 | U15: 17904.6 | V15: =T15+U15 -> 17904.6 | W15: =B15+E15+H15+K15+N15+Q15+T15 -> 0 | X15: =C15+F15+I15+L15+O15+R15+U15 -> 17904.6 | Y15: =W15+X15 -> 17904.6
A16: Contador Raymundo | C16: 3000 | D16: =B16+C16 -> 3000 | G16: =E16+F16 -> 0 | J16: =H16+I16 -> 0 | M16: =K16+L16 -> 0 | P16: =N16+O16 -> 0 | S16: =Q16+R16 -> 0 | V16: =T16+U16 -> 0 | W16: =B16+E16+H16+K16+N16+Q16+T16 -> 0 | X16: =C16+F16+I16+L16+O16+R16+U16 -> 3000 | Y16: =W16+X16 -> 3000
A17: CIPSA (Control de Plagas) | D17: =B17+C17 -> 0 | G17: =E17+F17 -> 0 | J17: =H17+I17 -> 0 | M17: =K17+L17 -> 0 | P17: =N17+O17 -> 0 | S17: =Q17+R17 -> 0 | U17: 3886 | V17: =T17+U17 -> 3886 | W17: =B17+E17+H17+K17+N17+Q17+T17 -> 0 | X17: =C17+F17+I17+L17+O17+R17+U17 -> 3886 | Y17: =W17+X17 -> 3886
A18: SIMA (CALIBRACION) | C18: 7500 | D18: =B18+C18 -> 7500 | F18: 12500 | G18: =E18+F18 -> 12500 | J18: =H18+I18 -> 0 | M18: =K18+L18 -> 0 | P18: =N18+O18 -> 0 | S18: =Q18+R18 -> 0 | V18: =T18+U18 -> 0 | W18: =B18+E18+H18+K18+N18+Q18+T18 -> 0 | X18: =C18+F18+I18+L18+O18+R18+U18 -> 20000 | Y18: =W18+X18 -> 20000
A19: TOTAL SERVICIOS | B19: =SUM(B4:B18) -> 24000 | C19: =SUM(C4:C18) -> 22500 | D19: =SUM(D4:D18) -> 46500 | E19: =SUM(E4:E18) -> 44954.48 | F19: =SUM(F4:F18) -> 72812.56 | G19: =SUM(G4:G18) -> 117767.04 | H19: =SUM(H4:H18) -> 19858.96 | I19: =SUM(I4:I18) -> 30198.2 | ... Y19: =SUM(Y4:Y18) -> 504959.94

Sheet 📊 Impuestos
A1: Detalle mensual por concepto — Impuestos
A2: Concepto | B2: Nov | E2: Dic | H2: Ene | K2: Feb | N2: Mar | Q2: Abr | T2: May | W2: TOTAL
B3: Pago | C3: Pendiente | D3: Total | E3: Pago | F3: Pendiente | G3: Total | H3: Pago | I3: Pendiente | J3: Total | K3: Pago | L3: Pendiente | M3: Total | N3: Pago | O3: Pendiente | P3: Total | Q3: Pago | R3: Pendiente | S3: Total | T3: Pago | U3: Pendiente | V3: Total | W3: Pago | X3: Pendiente | Y3: Total
A4: IMSS CXM | D4: =B4+C4 -> 0 | E4: 10000 | G4: =E4+F4 -> 10000 | I4: 10000 | J4: =H4+I4 -> 10000 | M4: =K4+L4 -> 0 | P4: =N4+O4 -> 0 | Q4: 32652.68 | S4: =Q4+R4 -> 32652.68 | T4: 26453.74 | U4: 149593.54 | V4: =T4+U4 -> 176047.28 | W4: =B4+E4+H4+K4+N4+Q4+T4 -> 69106.42 | X4: =C4+F4+I4+L4+O4+R4+U4 -> 159593.54 | Y4: =W4+X4 -> 228699.96
A5: IMSS | D5: =B5+C5 -> 0 | G5: =E5+F5 -> 0 | H5: 30000 | I5: 10000 | J5: =H5+I5 -> 40000 | L5: 120000 | M5: =K5+L5 -> 120000 | O5: 125000 | P5: =N5+O5 -> 125000 | R5: 25000 | S5: =Q5+R5 -> 25000 | V5: =T5+U5 -> 0 | W5: =B5+E5+H5+K5+N5+Q5+T5 -> 30000 | X5: =C5+F5+I5+L5+O5+R5+U5 -> 280000 | Y5: =W5+X5 -> 310000
A6: IMSS FV | D6: =B6+C6 -> 0 | G6: =E6+F6 -> 0 | J6: =H6+I6 -> 0 | M6: =K6+L6 -> 0 | P6: =N6+O6 -> 0 | Q6: 9676.45 | S6: =Q6+R6 -> 9676.45 | T6: 14685.06 | V6: =T6+U6 -> 14685.06 | W6: =B6+E6+H6+K6+N6+Q6+T6 -> 24361.51 | X6: =C6+F6+I6+L6+O6+R6+U6 -> 0 | Y6: =W6+X6 -> 24361.51
A7: Tenencias | B7: 17470 | D7: =B7+C7 -> 17470 | G7: =E7+F7 -> 0 | J7: =H7+I7 -> 0 | M7: =K7+L7 -> 0 | P7: =N7+O7 -> 0 | S7: =Q7+R7 -> 0 | V7: =T7+U7 -> 0 | W7: =B7+E7+H7+K7+N7+Q7+T7 -> 17470 | X7: =C7+F7+I7+L7+O7+R7+U7 -> 0 | Y7: =W7+X7 -> 17470
A8: IMPUESTOS LAR | D8: =B8+C8 -> 0 | G8: =E8+F8 -> 0 | J8: =H8+I8 -> 0 | M8: =K8+L8 -> 0 | P8: =N8+O8 -> 0 | S8: =Q8+R8 -> 0 | T8: 13428 | U8: 13428 | V8: =T8+U8 -> 26856 | W8: =B8+E8+H8+K8+N8+Q8+T8 -> 13428 | X8: =C8+F8+I8+L8+O8+R8+U8 -> 13428 | Y8: =W8+X8 -> 26856
A9: PAGO ACTA CONST FV PLUS | D9: =B9+C9 -> 0 | G9: =E9+F9 -> 0 | J9: =H9+I9 -> 0 | M9: =K9+L9 -> 0 | P9: =N9+O9 -> 0 | Q9: 11600 | S9: =Q9+R9 -> 11600 | V9: =T9+U9 -> 0 | W9: =B9+E9+H9+K9+N9+Q9+T9 -> 11600 | X9: =C9+F9+I9+L9+O9+R9+U9 -> 0 | Y9: =W9+X9 -> 11600
A10: IMPUESTOS LAR FEBRERO | D10: =B10+C10 -> 0 | G10: =E10+F10 -> 0 | J10: =H10+I10 -> 0 | M10: =K10+L10 -> 0 | P10: =N10+O10 -> 0 | S10: =Q10+R10 -> 0 | T10: 10801 | V10: =T10+U10 -> 10801 | W10: =B10+E10+H10+K10+N10+Q10+T10 -> 10801 | X10: =C10+F10+I10+L10+O10+R10+U10 -> 0 | Y10: =W10+X10 -> 10801
A11: IMSS (DEPOSITO A CUENTA AVV) | D11: =B11+C11 -> 0 | G11: =E11+F11 -> 0 | J11: =H11+I11 -> 0 | M11: =K11+L11 -> 0 | P11: =N11+O11 -> 0 | Q11: 10000 | S11: =Q11+R11 -> 10000 | V11: =T11+U11 -> 0 | W11: =B11+E11+H11+K11+N11+Q11+T11 -> 10000 | X11: =C11+F11+I11+L11+O11+R11+U11 -> 0 | Y11: =W11+X11 -> 10000
A12: CONVENIO IMSS CXM | D12: =B12+C12 -> 0 | G12: =E12+F12 -> 0 | J12: =H12+I12 -> 0 | M12: =K12+L12 -> 0 | P12: =N12+O12 -> 0 | R12: 32000 | S12: =Q12+R12 -> 32000 | V12: =T12+U12 -> 0 | W12: =B12+E12+H12+K12+N12+Q12+T12 -> 0 | X12: =C12+F12+I12+L12+O12+R12+U12 -> 32000 | Y12: =W12+X12 -> 32000
A13: IMPUESTOS OCTUBRE LAR | D13: =B13+C13 -> 0 | G13: =E13+F13 -> 0 | I13: 7900 | J13: =H13+I13 -> 7900 | M13: =K13+L13 -> 0 | P13: =N13+O13 -> 0 | S13: =Q13+R13 -> 0 | V13: =T13+U13 -> 0 | W13: =B13+E13+H13+K13+N13+Q13+T13 -> 0 | X13: =C13+F13+I13+L13+O13+R13+U13 -> 7900 | Y13: =W13+X13 -> 7900
A14: TOTAL IMPUESTOS | B14: =SUM(B4:B13) -> 17470 | C14: =SUM(C4:C13) -> 0 | D14: =SUM(D4:D13) -> 17470 | E14: =SUM(E4:E13) -> 10000 | F14: =SUM(F4:F13) -> 0 | G14: =SUM(G4:G13) -> 10000 | H14: =SUM(H4:H13) -> 30000 | I14: =SUM(I4:I13) -> 27900 | ... Y14: =SUM(Y4:Y13) -> 679688.47

Sheet 📊 Producto-Fruta
A1: Detalle mensual por concepto — Producto/Fruta
A2: Concepto | B2: Nov | E2: Dic | H2: Ene | K2: Feb | N2: Mar | Q2: Abr | T2: May | W2: TOTAL
B3: Pago | C3: Pendiente | D3: Total | E3: Pago | F3: Pendiente | G3: Total | H3: Pago | I3: Pendiente | J3: Total | K3: Pago | L3: Pendiente | M3: Total | N3: Pago | O3: Pendiente | P3: Total | Q3: Pago | R3: Pendiente | S3: Total | T3: Pago | U3: Pendiente | V3: Total | W3: Pago | X3: Pendiente | Y3: Total
A4: GUAYABAS LA ESPERANZA | D4: =B4+C4 -> 0 | E4: 50000 | G4: =E4+F4 -> 50000 | J4: =H4+I4 -> 0 | M4: =K4+L4 -> 0 | P4: =N4+O4 -> 0 | S4: =Q4+R4 -> 0 | V4: =T4+U4 -> 0 | W4: =B4+E4+H4+K4+N4+Q4+T4 -> 50000 | X4: =C4+F4+I4+L4+O4+R4+U4 -> 0 | Y4: =W4+X4 -> 50000
A5: PLATANO | B5: 37000 | D5: =B5+C5 -> 37000 | G5: =E5+F5 -> 0 | J5: =H5+I5 -> 0 | M5: =K5+L5 -> 0 | P5: =N5+O5 -> 0 | S5: =Q5+R5 -> 0 | V5: =T5+U5 -> 0 | W5: =B5+E5+H5+K5+N5+Q5+T5 -> 37000 | X5: =C5+F5+I5+L5+O5+R5+U5 -> 0 | Y5: =W5+X5 -> 37000
A6: PONCHO MADRIGAL (Fresa) | D6: =B6+C6 -> 0 | G6: =E6+F6 -> 0 | J6: =H6+I6 -> 0 | M6: =K6+L6 -> 0 | P6: =N6+O6 -> 0 | Q6: 18768 | S6: =Q6+R6 -> 18768 | V6: =T6+U6 -> 0 | W6: =B6+E6+H6+K6+N6+Q6+T6 -> 18768 | X6: =C6+F6+I6+L6+O6+R6+U6 -> 0 | Y6: =W6+X6 -> 18768
A7: TOTAL PRODUCTO/FRUTA | B7: =SUM(B4:B6) -> 37000 | C7: =SUM(C4:C6) -> 0 | D7: =SUM(D4:D6) -> 37000 | E7: =SUM(E4:E6) -> 50000 | F7: =SUM(F4:F6) -> 0 | G7: =SUM(G4:G6) -> 50000 | H7: =SUM(H4:H6) -> 0 | I7: =SUM(I4:I6) -> 0 | ... Y7: =SUM(Y4:Y6) -> 105768

Sheet 📊 LAR-Otros
A1: Detalle mensual por concepto — LAR/Otros
A2: Concepto | B2: Nov | E2: Dic | H2: Ene | K2: Feb | N2: Mar | Q2: Abr | T2: May | W2: TOTAL
B3: Pago | C3: Pendiente | D3: Total | E3: Pago | F3: Pendiente | G3: Total | H3: Pago | I3: Pendiente | J3: Total | K3: Pago | L3: Pendiente | M3: Total | N3: Pago | O3: Pendiente | P3: Total | Q3: Pago | R3: Pendiente | S3: Total | T3: Pago | U3: Pendiente | V3: Total | W3: Pago | X3: Pendiente | Y3: Total
A4: LAR seguro aveo | D4: =B4+C4 -> 0 | G4: =E4+F4 -> 0 | J4: =H4+I4 -> 0 | M4: =K4+L4 -> 0 | P4: =N4+O4 -> 0 | S4: =Q4+R4 -> 0 | T4: 2729 | V4: =T4+U4 -> 2729 | W4: =B4+E4+H4+K4+N4+Q4+T4 -> 2729 | X4: =C4+F4+I4+L4+O4+R4+U4 -> 0 | Y4: =W4+X4 -> 2729
A5: ADEUDO GALU | D5: =B5+C5 -> 0 | G5: =E5+F5 -> 0 | I5: 141000 | J5: =H5+I5 -> 141000 | L5: 141000 | M5: =K5+L5 -> 141000 | P5: =N5+O5 -> 0 | S5: =Q5+R5 -> 0 | V5: =T5+U5 -> 0 | W5: =B5+E5+H5+K5+N5+Q5+T5 -> 0 | X5: =C5+F5+I5+L5+O5+R5+U5 -> 282000 | Y5: =W5+X5 -> 282000
A6: GALU | D6: =B6+C6 -> 0 | G6: =E6+F6 -> 0 | J6: =H6+I6 -> 0 | M6: =K6+L6 -> 0 | P6: =N6+O6 -> 0 | S6: =Q6+R6 -> 0 | U6: 154000 | V6: =T6+U6 -> 154000 | W6: =B6+E6+H6+K6+N6+Q6+T6 -> 0 | X6: =C6+F6+I6+L6+O6+R6+U6 -> 154000 | Y6: =W6+X6 -> 154000
A7: TOTAL LAR/OTROS | B7: =SUM(B4:B6) -> 0 | C7: =SUM(C4:C6) -> 0 | D7: =SUM(D4:D6) -> 0 | E7: =SUM(E4:E6) -> 0 | F7: =SUM(F4:F6) -> 0 | G7: =SUM(G4:G6) -> 0 | H7: =SUM(H4:H6) -> 0 | I7: =SUM(I4:I6) -> 141000 | ... Y7: =SUM(Y4:Y6) -> 438729

Sheet Nómina-Personal (Pago)
A1: Acumulado mensual de Pago — Nómina/Personal
A3: Concepto | B3: Nov | C3: Dic | D3: Ene | E3: Feb | F3: Mar | G3: Abr | H3: May | I3: Total
A4: NOMINA FV | B4: 355000 | C4: 609298 | D4: 383000 | E4: 418000 | F4: 435000 | G4: 403000 | H4: 440000 | I4: =SUM(B4:H4) -> 3043298
A5: NOMINA CXM | B5: 73000 | C5: 65852.5 | D5: 68200 | E5: 70450 | F5: 86850 | G5: 92750 | H5: 98300 | I5: =SUM(B5:H5) -> 555402.5
A6: RAISA | B6: 80000 | C6: 0 | D6: 0 | E6: 86783.47 | F6: 54415.44 | G6: 40426.65 | H6: 68302.86 | I6: =SUM(B6:H6) -> 329928.42
A7: ARTURO GUERRERO | B7: 80000 | C7: 160000 | D7: 0 | E7: 0 | F7: 0 | G7: 0 | H7: 0 | I7: =SUM(B7:H7) -> 240000
A8: OMAR GUERRERO | B8: 0 | C8: 0 | D8: 0 | E8: 0 | F8: 0 | G8: 185800 | H8: 0 | I8: =SUM(B8:H8) -> 185800
A9: ALEX Y RAFA | B9: 30000 | C9: 40000 | D9: 15000 | E9: 49999.8 | F9: 10000 | G9: 20000 | H9: 20000 | I9: =SUM(B9:H9) -> 184999.8
A10: Cristian Ramirez | B10: 0 | C10: 67200 | D10: 0 | E10: 28500 | F10: 0 | G10: 0 | H10: 0 | I10: =SUM(B10:H10) -> 95700
A11: LALO AGUIRRE | B11: 0 | C11: 22846.25 | D11: 0 | E11: 14045.02 | F11: 6811.7 | G11: 0 | H11: 0 | I11: =SUM(B11:H11) -> 43702.97
A12: OMAR | B12: 0 | C12: 0 | D12: 37500 | E12: 0 | F12: 0 | G12: 0 | H12: 0 | I12: =SUM(B12:H12) -> 37500
A13: NOMINA JACONA | B13: 0 | C13: 0 | D13: 0 | E13: 0 | F13: 21600 | G13: 12000 | H13: 0 | I13: =SUM(B13:H13) -> 33600
A14: MATERIAL RAISA | B14: 0 | C14: 0 | D14: 0 | E14: 0 | F14: 0 | G14: 24644.75 | H14: 0 | I14: =SUM(B14:H14) -> 24644.75
A15: JOSE "CARAS" EQUIPO REFRIGERACION | B15: 0 | C15: 0 | D15: 0 | E15: 0 | F15: 0 | G15: 0 | H15: 20000 | I15: =SUM(B15:H15) -> 20000
... A28: TRANSPORTE LORE | B28: 0 | C28: 0 | D28: 0 | E28: 0 | F28: 0 | G28: 0 | H28: 0 | I28: =SUM(B28:H28) -> 0
A29: TOTAL PAGO NÓMINA/PERSONAL | B29: =SUM(B4:B28) -> 650006 | C29: =SUM(C4:C28) -> 972504.75 | D29: =SUM(D4:D28) -> 519300 | E29: =SUM(E4:E28) -> 667778.29 | F29: =SUM(F4:F28) -> 614677.14 | G29: =SUM(G4:G28) -> 811856.43 | H29: =SUM(H4:H28) -> 673111.09 | I29: =SUM(I4:I28) -> 4909233.7

Sheet Empaque-Material (Pago)
A1: Acumulado mensual de Pago — Empaque/Material
A3: Concepto | B3: Nov | C3: Dic | D3: Ene | E3: Feb | F3: Mar | G3: Abr | H3: May | I3: Total
A4: PATAGONIA CAJA CARTON y 30 lbs | B4: 0 | C4: 0 | D4: 0 | E4: 0 | F4: 0 | G4: 0 | H4: 153555 | I4: =SUM(B4:H4) -> 153555
A5: CAJA CARTON (PATAGONIA) 20 y 30 lbs | B5: 0 | C5: 0 | D5: 9802 | E5: 19604 | F5: 1896.6 | G5: 95845 | H5: 0 | I5: =SUM(B5:H5) -> 127147.6
A6: CAJA RUTH GDL | B6: 0 | C6: 0 | D6: 0 | E6: 77328.91 | F6: 20000 | G6: 0 | H6: 0 | I6: =SUM(B6:H6) -> 97328.91
A7: CAJA CARTON (PATAGONIA) | B7: 0 | C7: 58812 | D7: 3897.6 | E7: 0 | F7: 0 | G7: 0 | H7: 0 | I7: =SUM(B7:H7) -> 62709.6
A8: CAJA RUTH GDLMK BOXES | B8: 0 | C8: 0 | D8: 0 | E8: 0 | F8: 0 | G8: 61642.4 | H8: 0 | I8: =SUM(B8:H8) -> 61642.4
A9: JOSE HDEZ GARCIA (PAGO TARIMA) | B9: 0 | C9: 0 | D9: 0 | E9: 0 | F9: 0 | G9: 15370 | H9: 30740 | I9: =SUM(B9:H9) -> 46110
A10: BOLSA 30 LBS CHAVINDA | B10: 0 | C10: 0 | D10: 0 | E10: 14500 | F10: 0 | G10: 18000 | H10: 0 | I10: =SUM(B10:H10) -> 32500
A11: Ing Aguilar , embolsadora | B11: 15000 | C11: 12000 | D11: 0 | E11: 0 | F11: 0 | G11: 0 | H11: 0 | I11: =SUM(B11:H11) -> 27000
A12: CAJA PATAGONIA | B12: 0 | C12: 0 | D12: 16800 | E12: 0 | F12: 0 | G12: 0 | H12: 0 | I12: =SUM(B12:H12) -> 16800
A13: EMBAPACK | B13: 0 | C13: 5000 | D13: 0 | E13: 9856.45 | F13: 0 | G13: 0 | H13: 0 | I13: =SUM(B13:H13) -> 14856.45
A14: EMBAPACK Bolsa Verde) | B14: 0 | C14: 0 | D14: 0 | E14: 0 | F14: 1493.5 | G14: 13310.12 | H14: 0 | I14: =SUM(B14:H14) -> 14803.62
A15: Edgar Joel Vega Martínez (Emplaye) | B15: 0 | C15: 0 | D15: 0 | E15: 2728.32 | F15: 3410 | G15: 3970.21 | H15: 4235.94 | I15: =SUM(B15:H15) -> 14344.47
... A33: TARIMA | B33: 0 | C33: 0 | D33: 0 | E33: 0 | F33: 0 | G33: 0 | H33: 0 | I33: =SUM(B33:H33) -> 0
A34: TOTAL PAGO EMPAQUE/MATERIAL | B34: =SUM(B4:B33) -> 15000 | C34: =SUM(C4:C33) -> 95580.39 | D34: =SUM(D4:D33) -> 34481.54 | E34: =SUM(E4:E33) -> 124017.68 | F34: =SUM(F4:F33) -> 29668.1 | G34: =SUM(G4:G33) -> 227823.73 | H34: =SUM(H4:H33) -> 215479.03 | I34: =SUM(I4:I33) -> 742050.47

Sheet Otros (Pago)
A1: Acumulado mensual de Pago — Otros
A3: Concepto | B3: Nov | C3: Dic | D3: Ene | E3: Feb | F3: Mar | G3: Abr | H3: May | I3: Total
A4: AVV (PAGO SANTANDER) | B4: 0 | C4: 280000 | D4: 0 | E4: 0 | F4: 0 | G4: 0 | H4: 0 | I4: =SUM(B4:H4) -> 280000
A5: AVV (PAGO MONARCA) | B5: 0 | C5: 260435 | D5: 0 | E5: 0 | F5: 0 | G5: 0 | H5: 0 | I5: =SUM(B5:H5) -> 260435
A6: AVV (PAGO SANTANDERT) | B6: 0 | C6: 83200 | D6: 0 | E6: 0 | F6: 0 | G6: 0 | H6: 0 | I6: =SUM(B6:H6) -> 83200
A7: Alejandro Rodriguez | B7: 0 | C7: 0 | D7: 0 | E7: 20000 | F7: 40000 | G7: 0 | H7: 0 | I7: =SUM(B7:H7) -> 60000
A8: AVV (MONARCA) | B8: 0 | C8: 0 | D8: 0 | E8: 0 | F8: 50000 | G8: 0 | H8: 0 | I8: =SUM(B8:H8) -> 50000
A9: TRAMITES CFE | B9: 0 | C9: 0 | D9: 0 | E9: 0 | F9: 14500 | G9: 0 | H9: 0 | I9: =SUM(B9:H9) -> 14500
A10: AVV MONARCA | B10: 0 | C10: 0 | D10: 0 | E10: 0 | F10: 0 | G10: 0 | H10: 11000 | I10: =SUM(B10:H10) -> 11000
A11: CONTRATO REIMER (Lic Carlos) | B11: 0 | C11: 9280 | D11: 0 | E11: 0 | F11: 0 | G11: 0 | H11: 0 | I11: =SUM(B11:H11) -> 9280
A12: FRENOS CAMIONETA JESUS | B12: 0 | C12: 0 | D12: 0 | E12: 0 | F12: 8120 | G12: 0 | H12: 0 | I12: =SUM(B12:H12) -> 8120
A13: VERIFICACION FLOSOL | B13: 0 | C13: 0 | D13: 0 | E13: 8000 | F13: 0 | G13: 0 | H13: 0 | I13: =SUM(B13:H13) -> 8000
A14: ROCIO IMPI | B14: 0 | C14: 0 | D14: 0 | E14: 0 | F14: 7540 | G14: 0 | H14: 0 | I14: =SUM(B14:H14) -> 7540
A15: COMPRA LAPTOP | B15: 0 | C15: 0 | D15: 0 | E15: 0 | F15: 7499 | G15: 0 | H15: 0 | I15: =SUM(B15:H15) -> 7499
... A34: gastos | B34: 0 | C34: 0 | D34: 0 | E34: 0 | F34: 0 | G34: 0 | H34: 0 | I34: =SUM(B34:H34) -> 0
A35: TOTAL PAGO OTROS | B35: =SUM(B4:B34) -> 0 | C35: =SUM(C4:C34) -> 638935.4 | D35: =SUM(D4:D34) -> 2041.71 | E35: =SUM(E4:E34) -> 36900 | F35: =SUM(F4:F34) -> 132560.41 | G35: =SUM(G4:G34) -> 9159.56 | H35: =SUM(H4:H34) -> 18269 | I35: =SUM(I4:I34) -> 837866.08

Sheet Servicios (Pago)
A1: Acumulado mensual de Pago — Servicios
A3: Concepto | B3: Nov | C3: Dic | D3: Ene | E3: Feb | F3: Mar | G3: Abr | H3: May | I3: Total
A4: Honorarios contador | B4: 0 | C4: 9588.28 | D4: 19858.96 | E4: 16218.6 | F4: 29133.384 | G4: 30206.19 | H4: 41095.404 | I4: =SUM(B4:H4) -> 146100.82
A5: DEPACHO GARNICA | B5: 18000 | C5: 0 | D5: 0 | E5: 0 | F5: 0 | G5: 8952.3 | H5: 8952.3 | I5: =SUM(B5:H5) -> 35904.6
A6: CIPSA | B6: 6000 | C6: 8352 | D6: 0 | E6: 0 | F6: 3828 | G6: 5568 | H6: 0 | I6: =SUM(B6:H6) -> 23748
A7: GLADYS (CERTIFICACION) | B7: 0 | C7: 0 | D7: 0 | E7: 0 | F7: 0 | G7: 14500 | H7: 0 | I7: =SUM(B7:H7) -> 14500
A8: telefono | B8: 0 | C8: 12000 | D8: 0 | E8: 0 | F8: 0 | G8: 0 | H8: 0 | I8: =SUM(B8:H8) -> 12000
A9: Primus Lab | B9: 0 | C9: 3014.2 | D9: 0 | E9: 0 | F9: 0 | G9: 2277.13 | H9: 6086.26 | I9: =SUM(B9:H9) -> 11377.59
A10: Contador Carlos | B10: 0 | C10: 10000 | D10: 0 | E10: 0 | F10: 0 | G10: 0 | H10: 0 | I10: =SUM(B10:H10) -> 10000
A11: SANICHEM | B11: 0 | C11: 0 | D11: 0 | E11: 0 | F11: 0 | G11: 0 | H11: 6042.2 | I11: =SUM(B11:H11) -> 6042.2
A12: IMPRENTA BERNARDO | B12: 0 | C12: 0 | D12: 0 | E12: 0 | F12: 0 | G12: 2900 | H12: 0 | I12: =SUM(B12:H12) -> 2900
A13: TRES GUERRAS | B13: 0 | C13: 0 | D13: 0 | E13: 0 | F13: 0 | G13: 2516.21 | H13: 0 | I13: =SUM(B13:H13) -> 2516.21
A14: Contador Reymundo | B14: 0 | C14: 2000 | D14: 0 | E14: 0 | F14: 0 | G14: 0 | H14: 0 | I14: =SUM(B14:H14) -> 2000
A15: DEPACHO GARNICA (Pago Febrero 2026) | B15: 0 | C15: 0 | D15: 0 | E15: 0 | F15: 0 | G15: 0 | H15: 0 | I15: =SUM(B15:H15) -> 0
... A18: SIMA (CALIBRACION) | B18: 0 | C18: 0 | D18: 0 | E18: 0 | F18: 0 | G18: 0 | H18: 0 | I18: =SUM(B18:H18) -> 0
A19: TOTAL PAGO SERVICIOS | B19: =SUM(B4:B18) -> 24000 | C19: =SUM(C4:C18) -> 44954.48 | D19: =SUM(D4:D18) -> 19858.96 | E19: =SUM(E4:E18) -> 16218.6 | F19: =SUM(F4:F18) -> 32961.384 | G19: =SUM(G4:G18) -> 66919.83 | H19: =SUM(H4:H18) -> 62176.164 | I19: =SUM(I4:I18) -> 267089.42

Sheet Impuestos (Pago)
A1: Acumulado mensual de Pago — Impuestos
A3: Concepto | B3: Nov | C3: Dic | D3: Ene | E3: Feb | F3: Mar | G3: Abr | H3: May | I3: Total
A4: IMSS CXM | B4: 0 | C4: 10000 | D4: 0 | E4: 0 | F4: 0 | G4: 32652.68 | H4: 26453.74 | I4: =SUM(B4:H4) -> 69106.42
A5: IMSS | B5: 0 | C5: 0 | D5: 30000 | E5: 0 | F5: 0 | G5: 0 | H5: 0 | I5: =SUM(B5:H5) -> 30000
A6: IMSS FV | B6: 0 | C6: 0 | D6: 0 | E6: 0 | F6: 0 | G6: 9676.45 | H6: 14685.06 | I6: =SUM(B6:H6) -> 24361.51
A7: Tenencias | B7: 17470 | C7: 0 | D7: 0 | E7: 0 | F7: 0 | G7: 0 | H7: 0 | I7: =SUM(B7:H7) -> 17470
A8: IMPUESTOS LAR | B8: 0 | C8: 0 | D8: 0 | E8: 0 | F8: 0 | G8: 0 | H8: 13428 | I8: =SUM(B8:H8) -> 13428
A9: PAGO ACTA CONST FV PLUS | B9: 0 | C9: 0 | D9: 0 | E9: 0 | F9: 0 | G9: 11600 | H9: 0 | I9: =SUM(B9:H9) -> 11600
A10: IMPUESTOS LAR FEBRERO | B10: 0 | C10: 0 | D10: 0 | E10: 0 | F10: 0 | G10: 0 | H10: 10801 | I10: =SUM(B10:H10) -> 10801
A11: IMSS (DEPOSITO A CUENTA AVV) | B11: 0 | C11: 0 | D11: 0 | E11: 0 | F11: 0 | G11: 10000 | H11: 0 | I11: =SUM(B11:H11) -> 10000
A12: CONVENIO IMSS CXM | B12: 0 | C12: 0 | D12: 0 | E12: 0 | F12: 0 | G12: 0 | H12: 0 | I12: =SUM(B12:H12) -> 0
A13: IMPUESTOS OCTUBRE LAR | B13: 0 | C13: 0 | D13: 0 | E13: 0 | F13: 0 | G13: 0 | H13: 0 | I13: =SUM(B13:H13) -> 0
